Workbook

Sheet الخطة واللجنة
A1: خطة المرحلة الأولى للاعتماد البرامجي: التحقق من الأدلة وتحديد الفجوات
A2: الهدف: التحقق من وجود أدلة كل معيار وجودتها في البرنامجين، وتحديد الفجوات وخطة معالجتها خلال 6 أسابيع.
A4: البرنامج الأول | B4: بكالوريوس علوم البيانات
A5: البرنامج الثاني | B5: بكالوريوس علوم الحاسب
A7: ① الخطة الزمنية
A8: الأسبوع | B8: العمل | C8: المسؤول | D8: المخرج | E8: تم ✓
A9: 1 | B9: اجتماع الانطلاق: شرح الدليل وطريقة التقييم، توزيع المهام، إنشاء مجلد الأدلة (مجلد لكل برنامج ← لكل معيار)، وتقييم 3 أدلة معاً لتوحيد الحكم | C9: رئيس اللجنة + المنسق | D9: توزيع معتمد + مجلد أدلة جاهز
A10: 2 – 3 | B10: جمع الأدلة للبرنامجين معاً وتعبئة "حالة الدليل" و"سبب النقص" في ورقتي الفحص، ومخاطبة الجهات المساندة للأدلة المؤسسية | C10: كل عضو في معاييره | D10: ورقتا الفحص معبأتان
A11: 4 | B11: مراجعة متقاطعة: يراجع كل عضو عمل زميله في البرنامج الآخر، ويراجع الرئيس المعايير الأساسية ★ | C11: الأعضاء + رئيس اللجنة | D11: نتائج مراجَعة ومعتمدة
A12: 5 | B12: كتابة الإجراء المطلوب والموعد لكل دليل ناقص، وتمييز الفجوات المشتركة بين البرنامجين لمعالجتها مرة واحدة | C12: كل عضو في معاييره | D12: خطة معالجة الفجوات
A13: 6 | B13: إعداد تقرير الجاهزية من ورقة الملخص وعرضه على مجلس القسم/الكلية لاعتماد خطة المعالجة | C13: رئيس اللجنة + المنسق | D13: تقرير جاهزية معتمد
A15: اجتماع متابعة أسبوعي قصير (45 دقيقة) يراجع ورقة الملخص والعوائق.
A17: ② توزيع اللجنة (اكتب الأسماء في الخلايا الصفراء)
A18: م | B18: الاسم | C18: الدور | D18: المعايير المكلّف بها | E18: عدد الأدلة
A19: 1 | B19: عضو 1 | C19: رئيس اللجنة | D19: محور جودة التدريس وتقييم الطالب (2-3) للبرنامجين + مراجعة المعايير الأساسية ★ | E19: =COUNTIF('فحص-البرنامج1'!$E:$E,B19)+COUNTIF('فحص-البرنامج2'!$E:$E,B19) -> 50
A20: 2 | B20: عضو 2 | C20: منسق اللجنة (مسؤول الأدلة والملخص) | D20: مجال مصادر التعلم والمرافق (5) للبرنامجين + تنظيم مجلد الأدلة | E20: =COUNTIF('فحص-البرنامج1'!$E:$E,B20)+COUNTIF('فحص-البرنامج2'!$E:$E,B20) -> 38
A21: 3 | B21: عضو 3 | C21: عضو | D21: مجال إدارة البرنامج وضمان الجودة (1) – البرنامج الأول | E21: =COUNTIF('فحص-البرنامج1'!$E:$E,B21)+COUNTIF('فحص-البرنامج2'!$E:$E,B21) -> 52
A22: 4 | B22: عضو 4 | C22: عضو | D22: مجال إدارة البرنامج وضمان الجودة (1) – البرنامج الثاني | E22: =COUNTIF('فحص-البرنامج1'!$E:$E,B22)+COUNTIF('فحص-البرنامج2'!$E:$E,B22) -> 52
A23: 5 | B23: عضو 5 | C23: عضو | D23: نواتج التعلم والمنهج الدراسي (2-1، 2-2) – البرنامج الأول | E23: =COUNTIF('فحص-البرنامج1'!$E:$E,B23)+COUNTIF('فحص-البرنامج2'!$E:$E,B23) -> 50
A24: 6 | B24: عضو 6 | C24: عضو | D24: نواتج التعلم والمنهج الدراسي (2-1، 2-2) – البرنامج الثاني | E24: =COUNTIF('فحص-البرنامج1'!$E:$E,B24)+COUNTIF('فحص-البرنامج2'!$E:$E,B24) -> 50
A25: 7 | B25: عضو 7 | C25: عضو | D25: مجالا الطالب (3) وهيئة التدريس (4) – البرنامج الأول | E25: =COUNTIF('فحص-البرنامج1'!$E:$E,B25)+COUNTIF('فحص-البرنامج2'!$E:$E,B25) -> 58
A26: 8 | B26: عضو 8 | C26: عضو | D26: مجالا الطالب (3) وهيئة التدريس (4) – البرنامج الثاني | E26: =COUNTIF('فحص-البرنامج1'!$E:$E,B26)+COUNTIF('فحص-البرنامج2'!$E:$E,B26) -> 58
A27: المراجعة المتقاطعة (الأسبوع 4): العضو 3 ↔ 4، العضو 5 ↔ 6، العضو 7 ↔ 8، ويراجع الرئيس عمل المنسق، ويراجع العضوان 5 و6 عمل الرئيس.
A30: ③ طريقة التقييم (لكل دليل خانتان فقط)
A31: الخانة | B31: الاختيارات
A32: حالة الدليل | B32: متوفر ومكتمل • متوفر ويحتاج تحسين • غير متوفر
A33: سبب النقص (إن وُجد) | B33: غير معتمد • غير محدّث • لا يغطي المعيار كاملاً • لا يثبت التطبيق الفعلي • لا توجد نتائج وتحسين
A34: الدليل "المكتمل" | B34: هو الدليل المعتمد رسمياً، المحدَّث، الذي يغطي المعيار كاملاً، ويثبت التطبيق الفعلي، ويتضمن نتائج وتحسيناً مبنياً عليها
A35: الأولوية (تلقائية) | B35: عالية: إذا كان الدليل غير متوفر أو كان المعيار أساسياً ★ • متوسطة: بقية الأدلة التي تحتاج تحسيناً
A36: المعايير الأساسية ★ | B36: 15 معياراً مظللة بالأصفر في ورقتي الفحص – نبدأ بها لأنها تؤثر مباشرة في قرار الاعتماد

Sheet الملخص
A1: ملخص الجاهزية (يتحدث تلقائياً)
A2: نسبة الاكتمال = الأدلة المتوفرة والمكتملة ÷ إجمالي الأدلة. استخدم الفلتر في ورقة الفحص على عمود "حالة الدليل" لعرض الفجوات.
A4: ='الخطة واللجنة'!$B$4 -> بكالوريوس علوم البيانات
A5: المجال | B5: عدد الأدلة | C5: مكتمل | D5: يحتاج تحسين | E5: غير متوفر | F5: لم يُقيَّم بعد | G5: نسبة الاكتمال | H5: فجوات عالية الأولوية
A6: 1. إدارة البرنامج وضمان جودته | B6: =COUNTIF('فحص-البرنامج1'!$A$4:$A$207,"*1") -> 52 | C6: =COUNTIFS('فحص-البرنامج1'!$A$4:$A$207,"*1",'فحص-البرنامج1'!$F$4:$F$207,"متوفر ومكتمل") -> 0 | D6: =COUNTIFS('فحص-البرنامج1'!$A$4:$A$207,"*1",'فحص-البرنامج1'!$F$4:$F$207,"متوفر ويحتاج تحسين") -> 0 | E6: =COUNTIFS('فحص-البرنامج1'!$A$4:$A$207,"*1",'فحص-البرنامج1'!$F$4:$F$207,"غير متوفر") -> 0 | F6: =B6-SUM(C6:E6) -> 52 | G6: =IF(B6=0,0,C6/B6) -> 0 | H6: =COUNTIFS('فحص-البرنامج1'!$A$4:$A$207,"*1",'فحص-البرنامج1'!$H$4:$H$207,"عالية") -> 0
A7: 2. التعليم والتعلم | B7: =COUNTIF('فحص-البرنامج1'!$A$4:$A$207,"*2") -> 75 | C7: =COUNTIFS('فحص-البرنامج1'!$A$4:$A$207,"*2",'فحص-البرنامج1'!$F$4:$F$207,"متوفر ومكتمل") -> 0 | D7: =COUNTIFS('فحص-البرنامج1'!$A$4:$A$207,"*2",'فحص-البرنامج1'!$F$4:$F$207,"متوفر ويحتاج تحسين") -> 0 | E7: =COUNTIFS('فحص-البرنامج1'!$A$4:$A$207,"*2",'فحص-البرنامج1'!$F$4:$F$207,"غير متوفر") -> 0 | F7: =B7-SUM(C7:E7) -> 75 | G7: =IF(B7=0,0,C7/B7) -> 0 | H7: =COUNTIFS('فحص-البرنامج1'!$A$4:$A$207,"*2",'فحص-البرنامج1'!$H$4:$H$207,"عالية") -> 0
A8: 3. الطالب | B8: =COUNTIF('فحص-البرنامج1'!$A$4:$A$207,"*3") -> 32 | C8: =COUNTIFS('فحص-البرنامج1'!$A$4:$A$207,"*3",'فحص-البرنامج1'!$F$4:$F$207,"متوفر ومكتمل") -> 0 | D8: =COUNTIFS('فحص-البرنامج1'!$A$4:$A$207,"*3",'فحص-البرنامج1'!$F$4:$F$207,"متوفر ويحتاج تحسين") -> 0 | E8: =COUNTIFS('فحص-البرنامج1'!$A$4:$A$207,"*3",'فحص-البرنامج1'!$F$4:$F$207,"غير متوفر") -> 0 | F8: =B8-SUM(C8:E8) -> 32 | G8: =IF(B8=0,0,C8/B8) -> 0 | H8: =COUNTIFS('فحص-البرنامج1'!$A$4:$A$207,"*3",'فحص-البرنامج1'!$H$4:$H$207,"عالية") -> 0
A9: 4. هيئة التدريس | B9: =COUNTIF('فحص-البرنامج1'!$A$4:$A$207,"*4") -> 26 | C9: =COUNTIFS('فحص-البرنامج1'!$A$4:$A$207,"*4",'فحص-البرنامج1'!$F$4:$F$207,"متوفر ومكتمل") -> 0 | D9: =COUNTIFS('فحص-البرنامج1'!$A$4:$A$207,"*4",'فحص-البرنامج1'!$F$4:$F$207,"متوفر ويحتاج تحسين") -> 0 | E9: =COUNTIFS('فحص-البرنامج1'!$A$4:$A$207,"*4",'فحص-البرنامج1'!$F$4:$F$207,"غير متوفر") -> 0 | F9: =B9-SUM(C9:E9) -> 26 | G9: =IF(B9=0,0,C9/B9) -> 0 | H9: =COUNTIFS('فحص-البرنامج1'!$A$4:$A$207,"*4",'فحص-البرنامج1'!$H$4:$H$207,"عالية") -> 0
A10: 5. مصادر التعلم والمرافق والتجهيزات | B10: =COUNTIF('فحص-البرنامج1'!$A$4:$A$207,"*5") -> 19 | C10: =COUNTIFS('فحص-البرنامج1'!$A$4:$A$207,"*5",'فحص-البرنامج1'!$F$4:$F$207,"متوفر ومكتمل") -> 0 | D10: =COUNTIFS('فحص-البرنامج1'!$A$4:$A$207,"*5",'فحص-البرنامج1'!$F$4:$F$207,"متوفر ويحتاج تحسين") -> 0 | E10: =COUNTIFS('فحص-البرنامج1'!$A$4:$A$207,"*5",'فحص-البرنامج1'!$F$4:$F$207,"غير متوفر") -> 0 | F10: =B10-SUM(C10:E10) -> 19 | G10: =IF(B10=0,0,C10/B10) -> 0 | H10: =COUNTIFS('فحص-البرنامج1'!$A$4:$A$207,"*5",'فحص-البرنامج1'!$H$4:$H$207,"عالية") -> 0
A11: المعايير الأساسية ★ (15) | B11: =COUNTIF('فحص-البرنامج1'!$C$4:$C$207,"★") -> 66 | C11: =COUNTIFS('فحص-البرنامج1'!$C$4:$C$207,"★",'فحص-البرنامج1'!$F$4:$F$207,"متوفر ومكتمل") -> 0 | D11: =COUNTIFS('فحص-البرنامج1'!$C$4:$C$207,"★",'فحص-البرنامج1'!$F$4:$F$207,"متوفر ويحتاج تحسين") -> 0 | E11: =COUNTIFS('فحص-البرنامج1'!$C$4:$C$207,"★",'فحص-البرنامج1'!$F$4:$F$207,"غير متوفر") -> 0 | F11: =B11-SUM(C11:E11) -> 66 | G11: =IF(B11=0,0,C11/B11) -> 0 | H11: =COUNTIFS('فحص-البرنامج1'!$C$4:$C$207,"★",'فحص-البرنامج1'!$H$4:$H$207,"عالية") -> 0
A12: الإجمالي | B12: =COUNTIF('فحص-البرنامج1'!$A$4:$A$207,"*") -> 204 | C12: =COUNTIFS('فحص-البرنامج1'!$A$4:$A$207,"*",'فحص-البرنامج1'!$F$4:$F$207,"متوفر ومكتمل") -> 0 | D12: =COUNTIFS('فحص-البرنامج1'!$A$4:$A$207,"*",'فحص-البرنامج1'!$F$4:$F$207,"متوفر ويحتاج تحسين") -> 0 | E12: =COUNTIFS('فحص-البرنامج1'!$A$4:$A$207,"*",'فحص-البرنامج1'!$F$4:$F$207,"غير متوفر") -> 0 | F12: =B12-SUM(C12:E12) -> 204 | G12: =IF(B12=0,0,C12/B12) -> 0 | H12: =COUNTIFS('فحص-البرنامج1'!$A$4:$A$207,"*",'فحص-البرنامج1'!$H$4:$H$207,"عالية") -> 0
A14: ='الخطة واللجنة'!$B$5 -> بكالوريوس علوم الحاسب
A15: المجال | B15: عدد الأدلة | C15: مكتمل | D15: يحتاج تحسين | E15: غير متوفر | F15: لم يُقيَّم بعد | G15: نسبة الاكتمال | H15: فجوات عالية الأولوية
A16: 1. إدارة البرنامج وضمان جودته | B16: =COUNTIF('فحص-البرنامج2'!$A$4:$A$207,"*1") -> 52 | C16: =COUNTIFS('فحص-البرنامج2'!$A$4:$A$207,"*1",'فحص-البرنامج2'!$F$4:$F$207,"متوفر ومكتمل") -> 0 | D16: =COUNTIFS('فحص-البرنامج2'!$A$4:$A$207,"*1",'فحص-البرنامج2'!$F$4:$F$207,"متوفر ويحتاج تحسين") -> 0 | E16: =COUNTIFS('فحص-البرنامج2'!$A$4:$A$207,"*1",'فحص-البرنامج2'!$F$4:$F$207,"غير متوفر") -> 0 | F16: =B16-SUM(C16:E16) -> 52 | G16: =IF(B16=0,0,C16/B16) -> 0 | H16: =COUNTIFS('فحص-البرنامج2'!$A$4:$A$207,"*1",'فحص-البرنامج2'!$H$4:$H$207,"عالية") -> 0
A17: 2. التعليم والتعلم | B17: =COUNTIF('فحص-البرنامج2'!$A$4:$A$207,"*2") -> 75 | C17: =COUNTIFS('فحص-البرنامج2'!$A$4:$A$207,"*2",'فحص-البرنامج2'!$F$4:$F$207,"متوفر ومكتمل") -> 0 | D17: =COUNTIFS('فحص-البرنامج2'!$A$4:$A$207,"*2",'فحص-البرنامج2'!$F$4:$F$207,"متوفر ويحتاج تحسين") -> 0 | E17: =COUNTIFS('فحص-البرنامج2'!$A$4:$A$207,"*2",'فحص-البرنامج2'!$F$4:$F$207,"غير متوفر") -> 0 | F17: =B17-SUM(C17:E17) -> 75 | G17: =IF(B17=0,0,C17/B17) -> 0 | H17: =COUNTIFS('فحص-البرنامج2'!$A$4:$A$207,"*2",'فحص-البرنامج2'!$H$4:$H$207,"عالية") -> 0
A18: 3. الطالب | B18: =COUNTIF('فحص-البرنامج2'!$A$4:$A$207,"*3") -> 32 | C18: =COUNTIFS('فحص-البرنامج2'!$A$4:$A$207,"*3",'فحص-البرنامج2'!$F$4:$F$207,"متوفر ومكتمل") -> 0 | D18: =COUNTIFS('فحص-البرنامج2'!$A$4:$A$207,"*3",'فحص-البرنامج2'!$F$4:$F$207,"متوفر ويحتاج تحسين") -> 0 | E18: =COUNTIFS('فحص-البرنامج2'!$A$4:$A$207,"*3",'فحص-البرنامج2'!$F$4:$F$207,"غير متوفر") -> 0 | F18: =B18-SUM(C18:E18) -> 32 | G18: =IF(B18=0,0,C18/B18) -> 0 | H18: =COUNTIFS('فحص-البرنامج2'!$A$4:$A$207,"*3",'فحص-البرنامج2'!$H$4:$H$207,"عالية") -> 0
A19: 4. هيئة التدريس | B19: =COUNTIF('فحص-البرنامج2'!$A$4:$A$207,"*4") -> 26 | C19: =COUNTIFS('فحص-البرنامج2'!$A$4:$A$207,"*4",'فحص-البرنامج2'!$F$4:$F$207,"متوفر ومكتمل") -> 0 | D19: =COUNTIFS('فحص-البرنامج2'!$A$4:$A$207,"*4",'فحص-البرنامج2'!$F$4:$F$207,"متوفر ويحتاج تحسين") -> 0 | E19: =COUNTIFS('فحص-البرنامج2'!$A$4:$A$207,"*4",'فحص-البرنامج2'!$F$4:$F$207,"غير متوفر") -> 0 | F19: =B19-SUM(C19:E19) -> 26 | G19: =IF(B19=0,0,C19/B19) -> 0 | H19: =COUNTIFS('فحص-البرنامج2'!$A$4:$A$207,"*4",'فحص-البرنامج2'!$H$4:$H$207,"عالية") -> 0
A20: 5. مصادر التعلم والمرافق والتجهيزات | B20: =COUNTIF('فحص-البرنامج2'!$A$4:$A$207,"*5") -> 19 | C20: =COUNTIFS('فحص-البرنامج2'!$A$4:$A$207,"*5",'فحص-البرنامج2'!$F$4:$F$207,"متوفر ومكتمل") -> 0 | D20: =COUNTIFS('فحص-البرنامج2'!$A$4:$A$207,"*5",'فحص-البرنامج2'!$F$4:$F$207,"متوفر ويحتاج تحسين") -> 0 | E20: =COUNTIFS('فحص-البرنامج2'!$A$4:$A$207,"*5",'فحص-البرنامج2'!$F$4:$F$207,"غير متوفر") -> 0 | F20: =B20-SUM(C20:E20) -> 19 | G20: =IF(B20=0,0,C20/B20) -> 0 | H20: =COUNTIFS('فحص-البرنامج2'!$A$4:$A$207,"*5",'فحص-البرنامج2'!$H$4:$H$207,"عالية") -> 0
A21: المعايير الأساسية ★ (15) | B21: =COUNTIF('فحص-البرنامج2'!$C$4:$C$207,"★") -> 66 | C21: =COUNTIFS('فحص-البرنامج2'!$C$4:$C$207,"★",'فحص-البرنامج2'!$F$4:$F$207,"متوفر ومكتمل") -> 0 | D21: =COUNTIFS('فحص-البرنامج2'!$C$4:$C$207,"★",'فحص-البرنامج2'!$F$4:$F$207,"متوفر ويحتاج تحسين") -> 0 | E21: =COUNTIFS('فحص-البرنامج2'!$C$4:$C$207,"★",'فحص-البرنامج2'!$F$4:$F$207,"غير متوفر") -> 0 | F21: =B21-SUM(C21:E21) -> 66 | G21: =IF(B21=0,0,C21/B21) -> 0 | H21: =COUNTIFS('فحص-البرنامج2'!$C$4:$C$207,"★",'فحص-البرنامج2'!$H$4:$H$207,"عالية") -> 0
A22: الإجمالي | B22: =COUNTIF('فحص-البرنامج2'!$A$4:$A$207,"*") -> 204 | C22: =COUNTIFS('فحص-البرنامج2'!$A$4:$A$207,"*",'فحص-البرنامج2'!$F$4:$F$207,"متوفر ومكتمل") -> 0 | D22: =COUNTIFS('فحص-البرنامج2'!$A$4:$A$207,"*",'فحص-البرنامج2'!$F$4:$F$207,"متوفر ويحتاج تحسين") -> 0 | E22: =COUNTIFS('فحص-البرنامج2'!$A$4:$A$207,"*",'فحص-البرنامج2'!$F$4:$F$207,"غير متوفر") -> 0 | F22: =B22-SUM(C22:E22) -> 204 | G22: =IF(B22=0,0,C22/B22) -> 0 | H22: =COUNTIFS('فحص-البرنامج2'!$A$4:$A$207,"*",'فحص-البرنامج2'!$H$4:$H$207,"عالية") -> 0
A24: أكثر أسباب النقص
A25: سبب النقص | B25: ='الخطة واللجنة'!$B$4 -> بكالوريوس علوم البيانات | C25: ='الخطة واللجنة'!$B$5 -> بكالوريوس علوم الحاسب
A26: غير معتمد | B26: =COUNTIF('فحص-البرنامج1'!$G$4:$G$207,"غير معتمد") -> 0 | C26: =COUNTIF('فحص-البرنامج2'!$G$4:$G$207,"غير معتمد") -> 0
A27: غير محدّث | B27: =COUNTIF('فحص-البرنامج1'!$G$4:$G$207,"غير محدّث") -> 0 | C27: =COUNTIF('فحص-البرنامج2'!$G$4:$G$207,"غير محدّث") -> 0
A28: لا يغطي المعيار كاملاً | B28: =COUNTIF('فحص-البرنامج1'!$G$4:$G$207,"لا يغطي المعيار كاملاً") -> 0 | C28: =COUNTIF('فحص-البرنامج2'!$G$4:$G$207,"لا يغطي المعيار كاملاً") -> 0
A29: لا يثبت التطبيق الفعلي | B29: =COUNTIF('فحص-البرنامج1'!$G$4:$G$207,"لا يثبت التطبيق الفعلي") -> 0 | C29: =COUNTIF('فحص-البرنامج2'!$G$4:$G$207,"لا يثبت التطبيق الفعلي") -> 0
A30: لا توجد نتائج وتحسين | B30: =COUNTIF('فحص-البرنامج1'!$G$4:$G$207,"لا توجد نتائج وتحسين") -> 0 | C30: =COUNTIF('فحص-البرنامج2'!$G$4:$G$207,"لا توجد نتائج وتحسين") -> 0

Sheet فحص-البرنامج1
A1: ="فحص الأدلة – "&'الخطة واللجنة'!$B$4 -> فحص الأدلة – بكالوريوس علوم البيانات
A2: عبّئ الخلايا الصفراء فقط: اختر حالة الدليل، وإن كان ناقصاً اختر السبب واكتب الإجراء والموعد. الصفوف المظللة = معايير أساسية ★
A3: الرمز | B3: نص المعيار | C3: أساسي | D3: الدليل / الشاهد المقترح | E3: المسؤول | F3: حالة الدليل | G3: سبب النقص | H3: الأولوية | I3: الإجراء المطلوب | J3: الموعد | K3: رابط / مسار الدليل | L3: ملاحظات
A4: 1-1-1 | B4: تتسق رسالة البرنامج وأهدافه مع رسالة المؤسسة/الكلية وتوجّه جميع عملياته وأنشطته. | D4: مصفوفة اتساق رسالة وأهداف البرنامج مع رسالة وأهداف الجامعة والكلية. | E4: ='الخطة واللجنة'!$B$21 -> عضو 3 | H4: =IF(OR(F4="",F4="متوفر ومكتمل"),"",IF(OR(C4="★",F4="غير متوفر"),"عالية","متوسطة"))
A5: 1-1-1 | D5: إعلان رسالة وأهداف البرنامج على الموقع الإلكتروني للبرنامج. | E5: ='الخطة واللجنة'!$B$21 -> عضو 3 | H5: =IF(OR(F5="",F5="متوفر ومكتمل"),"",IF(OR(C5="★",F5="غير متوفر"),"عالية","متوسطة"))
A6: 1-1-1 | D6: الخطة التشغيلية للبرنامج وتقاريرها وتشمل البحث العلمي وخدمة المجتمع. | E6: ='الخطة واللجنة'!$B$21 -> عضو 3 | H6: =IF(OR(F6="",F6="متوفر ومكتمل"),"",IF(OR(C6="★",F6="غير متوفر"),"عالية","متوسطة"))
A7: 1-1-1 | D7: تقرير استطلاع رأي المستفيدين حول وضوح ونشر الرسالة والأهداف. | E7: ='الخطة واللجنة'!$B$21 -> عضو 3 | H7: =IF(OR(F7="",F7="متوفر ومكتمل"),"",IF(OR(C7="★",F7="غير متوفر"),"عالية","متوسطة"))
A8: 2-1-1 | B8: يتوفر لدى البرنامج العدد الكافي من الكوادر المؤهلة للقيام بالمهام الإدارية والمهنية والفنية، ولهم مهام وصلاحيات محددة. | C8: ★ | D8: قاعدة بيانات محدثة لأعضاء هيئة التدريس بالبرنامج والإداريين والفنيين. | E8: ='الخطة واللجنة'!$B$21 -> عضو 3 | H8: =IF(OR(F8="",F8="متوفر ومكتمل"),"",IF(OR(C8="★",F8="غير متوفر"),"عالية","متوسطة"))
A9: 2-1-1 | C9: ★ | D9: السير الذاتية لأعضاء هيئة التدريس، وقيادات البرنامج، والإداريين، والفنيين. | E9: ='الخطة واللجنة'!$B$21 -> عضو 3 | H9: =IF(OR(F9="",F9="متوفر ومكتمل"),"",IF(OR(C9="★",F9="غير متوفر"),"عالية","متوسطة"))
A10: 2-1-1 | C10: ★ | D10: نماذج من تشكيلات اللجان بالبرنامج محددة المهام. | E10: ='الخطة واللجنة'!$B$21 -> عضو 3 | H10: =IF(OR(F10="",F10="متوفر ومكتمل"),"",IF(OR(C10="★",F10="غير متوفر"),"عالية","متوسطة"))
A11: 2-1-1 | C11: ★ | D11: معايير اختيار القيادات الأكاديمية والإدارية. | E11: ='الخطة واللجنة'!$B$21 -> عضو 3 | H11: =IF(OR(F11="",F11="متوفر ومكتمل"),"",IF(OR(C11="★",F11="غير متوفر"),"عالية","متوسطة"))
A12: 2-1-1 | C12: ★ | D12: استبانة تقييم القيادات الأكاديمية والإدارية بالبرنامج. | E12: ='الخطة واللجنة'!$B$21 -> عضو 3 | H12: =IF(OR(F12="",F12="متوفر ومكتمل"),"",IF(OR(C12="★",F12="غير متوفر"),"عالية","متوسطة"))
A13: 3-1-1 | B13: يتوفر للبرنامج منظومة تحفيزية وبيئة أكاديمية داعمة. | D13: دليل جوائز التميز بالكلية/الجامعة. | E13: ='الخطة واللجنة'!$B$21 -> عضو 3 | H13: =IF(OR(F13="",F13="متوفر ومكتمل"),"",IF(OR(C13="★",F13="غير متوفر"),"عالية","متوسطة"))
A14: 3-1-1 | D14: نماذج من شهادات (تميز/تقدير) منسوبي البرنامج والإداريين والفنيين. | E14: ='الخطة واللجنة'!$B$21 -> عضو 3 | H14: =IF(OR(F14="",F14="متوفر ومكتمل"),"",IF(OR(C14="★",F14="غير متوفر"),"عالية","متوسطة"))
A15: 3-1-1 | D15: قائمة بالمرافق والتجهيزات التعليمية والبحثية للبرنامج. | E15: ='الخطة واللجنة'!$B$21 -> عضو 3 | H15: =IF(OR(F15="",F15="متوفر ومكتمل"),"",IF(OR(C15="★",F15="غير متوفر"),"عالية","متوسطة"))
A16: 3-1-1 | D16: قائمة بالمرافق والتجهيزات الخاصة بالأنشطة اللاصفية بالبرنامج. | E16: ='الخطة واللجنة'!$B$21 -> عضو 3 | H16: =IF(OR(F16="",F16="متوفر ومكتمل"),"",IF(OR(C16="★",F16="غير متوفر"),"عالية","متوسطة"))
A17: 3-1-1 | D17: تقييمات أعضاء هيئة التدريس والإداريين والفنيين والطلاب للمناخ التنظيمي والبيئة الأكاديمية. | E17: ='الخطة واللجنة'!$B$21 -> عضو 3 | H17: =IF(OR(F17="",F17="متوفر ومكتمل"),"",IF(OR(C17="★",F17="غير متوفر"),"عالية","متوسطة"))
A18: 4-1-1 | B18: يتم القياس المستمر لمؤشرات أداء البرنامج الرئيسة، وتُتخذ الإجراءات اللازمة للتحسين. | D18: تقرير مؤشرات الأداء الرئيسة للبرنامج. | E18: ='الخطة واللجنة'!$B$21 -> عضو 3 | H18: =IF(OR(F18="",F18="متوفر ومكتمل"),"",IF(OR(C18="★",F18="غير متوفر"),"عالية","متوسطة"))
A19: 4-1-1 | D19: تقرير إنجاز الخطة التشغيلية للبرنامج مع خطة التحسين. | E19: ='الخطة واللجنة'!$B$21 -> عضو 3 | H19: =IF(OR(F19="",F19="متوفر ومكتمل"),"",IF(OR(C19="★",F19="غير متوفر"),"عالية","متوسطة"))
A20: 5-1-1 | B20: يوثّق البرنامج وينشر السياسات والحقوق والواجبات الخاصة بمنسوبيه بصورة معلنة، ويطبق آليات تضمن النزاهة والعدالة والمساواة في جميع ممارساته الأكاديمية والإدارية بين شطري الطلاب والطالبات والفروع (إن وجدت). | D20: لوحة/دليل موضح فيه السياسات والحقوق والواجبات وتكون معلنة. | E20: ='الخطة واللجنة'!$B$21 -> عضو 3 | H20: =IF(OR(F20="",F20="متوفر ومكتمل"),"",IF(OR(C20="★",F20="غير متوفر"),"عالية","متوسطة"))
A21: 5-1-1 | D21: استطلاع رأي أعضاء هيئة التدريس والطلبة عن تطبيق إدارة البرنامج لآليات النزاهة والعدالة والمساواة. | E21: ='الخطة واللجنة'!$B$21 -> عضو 3 | H21: =IF(OR(F21="",F21="متوفر ومكتمل"),"",IF(OR(C21="★",F21="غير متوفر"),"عالية","متوسطة"))
A22: 5-1-1 | D22: الشواهد على مدى تكافؤ الإمكانيات المادية والبشرية بين شطري الطالب والطالبات. | E22: ='الخطة واللجنة'!$B$21 -> عضو 3 | H22: =IF(OR(F22="",F22="متوفر ومكتمل"),"",IF(OR(C22="★",F22="غير متوفر"),"عالية","متوسطة"))
A23: 5-1-1 | D23: تشكيل اللجان والمجالس العاملة بالقسم بما يتضمن إشراك الجنسين والفروع (إن وجدت)، وكذا تمويل الأبحاث والمشاريع وحضور المؤتمرات. | E23: ='الخطة واللجنة'!$B$21 -> عضو 3 | H23: =IF(OR(F23="",F23="متوفر ومكتمل"),"",IF(OR(C23="★",F23="غير متوفر"),"عالية","متوسطة"))
A24: 6-1-1 | B24: تستفيد إدارة البرنامج من آراء المختصين والخبراء في تشكيل لجنة استشارية متنوعة الأعضاء وموضحة المهام، وتخصص البرنامج في تقييم وتطوير وتحسين أدائه. | D24: قرار تشكيل اللجنة الاستشارية للبرنامج المتنوعة الأعضاء والموضح مهامها. | E24: ='الخطة واللجنة'!$B$21 -> عضو 3 | H24: =IF(OR(F24="",F24="متوفر ومكتمل"),"",IF(OR(C24="★",F24="غير متوفر"),"عالية","متوسطة"))
A25: 6-1-1 | D25: نماذج من محاضر اللجنة الاستشارية للبرنامج متضمنة التوصيات وخطط تفعيلها. | E25: ='الخطة واللجنة'!$B$21 -> عضو 3 | H25: =IF(OR(F25="",F25="متوفر ومكتمل"),"",IF(OR(C25="★",F25="غير متوفر"),"عالية","متوسطة"))
A26: 6-1-1 | D26: تقرير استطلاع رأي جهات التوظيف حول الخريجين وتوصيات وخطط التحسين. | E26: ='الخطة واللجنة'!$B$21 -> عضو 3 | H26: =IF(OR(F26="",F26="متوفر ومكتمل"),"",IF(OR(C26="★",F26="غير متوفر"),"عالية","متوسطة"))
A27: 6-1-1 | D27: محاضر مجلس القسم متضمنة مناقشة توصيات اللجنة الاستشارية واستطلاع رأي جهات التوظيف وأي مقترحات تطوير من خبراء التخصص. | E27: ='الخطة واللجنة'!$B$21 -> عضو 3 | H27: =IF(OR(F27="",F27="متوفر ومكتمل"),"",IF(OR(C27="★",F27="غير متوفر"),"عالية","متوسطة"))
A28: 7-1-1 | B28: تتيح إدارة البرنامج معلومات موثوقة ومحدّثة تُبرز إنجازات البرنامج بما يتناسب مع احتياجات المستفيدين. | D28: الدليل التعريفي للبرنامج. | E28: ='الخطة واللجنة'!$B$21 -> عضو 3 | H28: =IF(OR(F28="",F28="متوفر ومكتمل"),"",IF(OR(C28="★",F28="غير متوفر"),"عالية","متوسطة"))
A29: 7-1-1 | D29: الموقع الإلكتروني للبرنامج متضمناً توصيف البرنامج والمقررات الدراسية وأنشطته وإنجازاته محدّثاً. | E29: ='الخطة واللجنة'!$B$21 -> عضو 3 | H29: =IF(OR(F29="",F29="متوفر ومكتمل"),"",IF(OR(C29="★",F29="غير متوفر"),"عالية","متوسطة"))
A30: 7-1-1 | D30: أنشطة لجنة خدمة المجتمع للتعريف بالبرنامج وإمكاناته والخدمات التي يقدمها للمجتمع. | E30: ='الخطة واللجنة'!$B$21 -> عضو 3 | H30: =IF(OR(F30="",F30="متوفر ومكتمل"),"",IF(OR(C30="★",F30="غير متوفر"),"عالية","متوسطة"))
A31: 7-1-1 | D31: نماذج من إعلانات ولقاءات التعريف بالبرنامج مع المستفيدين. | E31: ='الخطة واللجنة'!$B$21 -> عضو 3 | H31: =IF(OR(F31="",F31="متوفر ومكتمل"),"",IF(OR(C31="★",F31="غير متوفر"),"عالية","متوسطة"))
A32: 7-1-1 | D32: نتائج استطلاع رأي المستفيدين حول إتاحة المعلومات الخاصة بالبرنامج. | E32: ='الخطة واللجنة'!$B$21 -> عضو 3 | H32: =IF(OR(F32="",F32="متوفر ومكتمل"),"",IF(OR(C32="★",F32="غير متوفر"),"عالية","متوسطة"))
A33: 8-1-1 | B33: تلتزم إدارة البرنامج بتفعيل قيم الأمانة العلمية وحقوق الملكية الفكرية وقواعد الممارسات الأخلاقية والسلوك القويم في جميع المجالات والأنشطة الأكاديمية والبحثية والإدارية والخدمية. | C33: ★ | D33: السياسات والإجراءات الموثقة التي يطبقها البرنامج بشأن عمليات الاقتباس والملكية الفكرية للطلبة وأعضاء هيئة التدريس. | E33: ='الخطة واللجنة'!$B$21 -> عضو 3 | H33: =IF(OR(F33="",F33="متوفر ومكتمل"),"",IF(OR(C33="★",F33="غير متوفر"),"عالية","متوسطة"))
A34: 8-1-1 | C34: ★ | D34: دليل الإطار الأخلاقي للطلبة ومنسوبي الجامعة. | E34: ='الخطة واللجنة'!$B$21 -> عضو 3 | H34: =IF(OR(F34="",F34="متوفر ومكتمل"),"",IF(OR(C34="★",F34="غير متوفر"),"عالية","متوسطة"))
A35: 8-1-1 | C35: ★ | D35: دليل أخلاقيات البحث العلمي. | E35: ='الخطة واللجنة'!$B$21 -> عضو 3 | H35: =IF(OR(F35="",F35="متوفر ومكتمل"),"",IF(OR(C35="★",F35="غير متوفر"),"عالية","متوسطة"))
A36: 8-1-1 | C36: ★ | D36: قائمة بالدورات التدريبية المتعلقة بقيم الأمانة العلمية وحقوق الملكية الفكرية وقواعد الممارسات الأخلاقية. | E36: ='الخطة واللجنة'!$B$21 -> عضو 3 | H36: =IF(OR(F36="",F36="متوفر ومكتمل"),"",IF(OR(C36="★",F36="غير متوفر"),"عالية","متوسطة"))
A37: 8-1-1 | C37: ★ | D37: نماذج من تعميمات رئيس القسم على ضرورة الالتزام بقيم الأمانة العلمية وحقوق الملكية الفكرية. | E37: ='الخطة واللجنة'!$B$21 -> عضو 3 | H37: =IF(OR(F37="",F37="متوفر ومكتمل"),"",IF(OR(C37="★",F37="غير متوفر"),"عالية","متوسطة"))
A38: 8-1-1 | C38: ★ | D38: عينات من تقارير فحص الاستلال العلمي لأعمال الطلبة. | E38: ='الخطة واللجنة'!$B$21 -> عضو 3 | H38: =IF(OR(F38="",F38="متوفر ومكتمل"),"",IF(OR(C38="★",F38="غير متوفر"),"عالية","متوسطة"))
A39: 9-1-1 | B39: تتبنى إدارة البرنامج آلية واضحة وإجراءات معتمدة من قِبل المؤسسة/الكلية للشكاوى والتظلم والقضايا التأديبية. | D39: سياسات وآليات الشكاوى والتظلم المعتمدة سواء للطالب أو أعضاء هيئة التدريس. | E39: ='الخطة واللجنة'!$B$21 -> عضو 3 | H39: =IF(OR(F39="",F39="متوفر ومكتمل"),"",IF(OR(C39="★",F39="غير متوفر"),"عالية","متوسطة"))
A40: 9-1-1 | D40: نماذج من محاضر الرفع بالشكاوى والتظلمات وقرارات الرد عليها. | E40: ='الخطة واللجنة'!$B$21 -> عضو 3 | H40: =IF(OR(F40="",F40="متوفر ومكتمل"),"",IF(OR(C40="★",F40="غير متوفر"),"عالية","متوسطة"))
...

Sheet فحص-البرنامج2
A1: ="فحص الأدلة – "&'الخطة واللجنة'!$B$5 -> فحص الأدلة – بكالوريوس علوم الحاسب
A2: عبّئ الخلايا الصفراء فقط: اختر حالة الدليل، وإن كان ناقصاً اختر السبب واكتب الإجراء والموعد. الصفوف المظللة = معايير أساسية ★
A3: الرمز | B3: نص المعيار | C3: أساسي | D3: الدليل / الشاهد المقترح | E3: المسؤول | F3: حالة الدليل | G3: سبب النقص | H3: الأولوية | I3: الإجراء المطلوب | J3: الموعد | K3: رابط / مسار الدليل | L3: ملاحظات
A4: 1-1-1 | B4: تتسق رسالة البرنامج وأهدافه مع رسالة المؤسسة/الكلية وتوجّه جميع عملياته وأنشطته. | D4: مصفوفة اتساق رسالة وأهداف البرنامج مع رسالة وأهداف الجامعة والكلية. | E4: ='الخطة واللجنة'!$B$22 -> عضو 4 | H4: =IF(OR(F4="",F4="متوفر ومكتمل"),"",IF(OR(C4="★",F4="غير متوفر"),"عالية","متوسطة"))
A5: 1-1-1 | D5: إعلان رسالة وأهداف البرنامج على الموقع الإلكتروني للبرنامج. | E5: ='الخطة واللجنة'!$B$22 -> عضو 4 | H5: =IF(OR(F5="",F5="متوفر ومكتمل"),"",IF(OR(C5="★",F5="غير متوفر"),"عالية","متوسطة"))
A6: 1-1-1 | D6: الخطة التشغيلية للبرنامج وتقاريرها وتشمل البحث العلمي وخدمة المجتمع. | E6: ='الخطة واللجنة'!$B$22 -> عضو 4 | H6: =IF(OR(F6="",F6="متوفر ومكتمل"),"",IF(OR(C6="★",F6="غير متوفر"),"عالية","متوسطة"))
A7: 1-1-1 | D7: تقرير استطلاع رأي المستفيدين حول وضوح ونشر الرسالة والأهداف. | E7: ='الخطة واللجنة'!$B$22 -> عضو 4 | H7: =IF(OR(F7="",F7="متوفر ومكتمل"),"",IF(OR(C7="★",F7="غير متوفر"),"عالية","متوسطة"))
A8: 2-1-1 | B8: يتوفر لدى البرنامج العدد الكافي من الكوادر المؤهلة للقيام بالمهام الإدارية والمهنية والفنية، ولهم مهام وصلاحيات محددة. | C8: ★ | D8: قاعدة بيانات محدثة لأعضاء هيئة التدريس بالبرنامج والإداريين والفنيين. | E8: ='الخطة واللجنة'!$B$22 -> عضو 4 | H8: =IF(OR(F8="",F8="متوفر ومكتمل"),"",IF(OR(C8="★",F8="غير متوفر"),"عالية","متوسطة"))
A9: 2-1-1 | C9: ★ | D9: السير الذاتية لأعضاء هيئة التدريس، وقيادات البرنامج، والإداريين، والفنيين. | E9: ='الخطة واللجنة'!$B$22 -> عضو 4 | H9: =IF(OR(F9="",F9="متوفر ومكتمل"),"",IF(OR(C9="★",F9="غير متوفر"),"عالية","متوسطة"))
A10: 2-1-1 | C10: ★ | D10: نماذج من تشكيلات اللجان بالبرنامج محددة المهام. | E10: ='الخطة واللجنة'!$B$22 -> عضو 4 | H10: =IF(OR(F10="",F10="متوفر ومكتمل"),"",IF(OR(C10="★",F10="غير متوفر"),"عالية","متوسطة"))
A11: 2-1-1 | C11: ★ | D11: معايير اختيار القيادات الأكاديمية والإدارية. | E11: ='الخطة واللجنة'!$B$22 -> عضو 4 | H11: =IF(OR(F11="",F11="متوفر ومكتمل"),"",IF(OR(C11="★",F11="غير متوفر"),"عالية","متوسطة"))
A12: 2-1-1 | C12: ★ | D12: استبانة تقييم القيادات الأكاديمية والإدارية بالبرنامج. | E12: ='الخطة واللجنة'!$B$22 -> عضو 4 | H12: =IF(OR(F12="",F12="متوفر ومكتمل"),"",IF(OR(C12="★",F12="غير متوفر"),"عالية","متوسطة"))
A13: 3-1-1 | B13: يتوفر للبرنامج منظومة تحفيزية وبيئة أكاديمية داعمة. | D13: دليل جوائز التميز بالكلية/الجامعة. | E13: ='الخطة واللجنة'!$B$22 -> عضو 4 | H13: =IF(OR(F13="",F13="متوفر ومكتمل"),"",IF(OR(C13="★",F13="غير متوفر"),"عالية","متوسطة"))
A14: 3-1-1 | D14: نماذج من شهادات (تميز/تقدير) منسوبي البرنامج والإداريين والفنيين. | E14: ='الخطة واللجنة'!$B$22 -> عضو 4 | H14: =IF(OR(F14="",F14="متوفر ومكتمل"),"",IF(OR(C14="★",F14="غير متوفر"),"عالية","متوسطة"))
A15: 3-1-1 | D15: قائمة بالمرافق والتجهيزات التعليمية والبحثية للبرنامج. | E15: ='الخطة واللجنة'!$B$22 -> عضو 4 | H15: =IF(OR(F15="",F15="متوفر ومكتمل"),"",IF(OR(C15="★",F15="غير متوفر"),"عالية","متوسطة"))
A16: 3-1-1 | D16: قائمة بالمرافق والتجهيزات الخاصة بالأنشطة اللاصفية بالبرنامج. | E16: ='الخطة واللجنة'!$B$22 -> عضو 4 | H16: =IF(OR(F16="",F16="متوفر ومكتمل"),"",IF(OR(C16="★",F16="غير متوفر"),"عالية","متوسطة"))
A17: 3-1-1 | D17: تقييمات أعضاء هيئة التدريس والإداريين والفنيين والطلاب للمناخ التنظيمي والبيئة الأكاديمية. | E17: ='الخطة واللجنة'!$B$22 -> عضو 4 | H17: =IF(OR(F17="",F17="متوفر ومكتمل"),"",IF(OR(C17="★",F17="غير متوفر"),"عالية","متوسطة"))
A18: 4-1-1 | B18: يتم القياس المستمر لمؤشرات أداء البرنامج الرئيسة، وتُتخذ الإجراءات اللازمة للتحسين. | D18: تقرير مؤشرات الأداء الرئيسة للبرنامج. | E18: ='الخطة واللجنة'!$B$22 -> عضو 4 | H18: =IF(OR(F18="",F18="متوفر ومكتمل"),"",IF(OR(C18="★",F18="غير متوفر"),"عالية","متوسطة"))
A19: 4-1-1 | D19: تقرير إنجاز الخطة التشغيلية للبرنامج مع خطة التحسين. | E19: ='الخطة واللجنة'!$B$22 -> عضو 4 | H19: =IF(OR(F19="",F19="متوفر ومكتمل"),"",IF(OR(C19="★",F19="غير متوفر"),"عالية","متوسطة"))
A20: 5-1-1 | B20: يوثّق البرنامج وينشر السياسات والحقوق والواجبات الخاصة بمنسوبيه بصورة معلنة، ويطبق آليات تضمن النزاهة والعدالة والمساواة في جميع ممارساته الأكاديمية والإدارية بين شطري الطلاب والطالبات والفروع (إن وجدت). | D20: لوحة/دليل موضح فيه السياسات والحقوق والواجبات وتكون معلنة. | E20: ='الخطة واللجنة'!$B$22 -> عضو 4 | H20: =IF(OR(F20="",F20="متوفر ومكتمل"),"",IF(OR(C20="★",F20="غير متوفر"),"عالية","متوسطة"))
A21: 5-1-1 | D21: استطلاع رأي أعضاء هيئة التدريس والطلبة عن تطبيق إدارة البرنامج لآليات النزاهة والعدالة والمساواة. | E21: ='الخطة واللجنة'!$B$22 -> عضو 4 | H21: =IF(OR(F21="",F21="متوفر ومكتمل"),"",IF(OR(C21="★",F21="غير متوفر"),"عالية","متوسطة"))
A22: 5-1-1 | D22: الشواهد على مدى تكافؤ الإمكانيات المادية والبشرية بين شطري الطالب والطالبات. | E22: ='الخطة واللجنة'!$B$22 -> عضو 4 | H22: =IF(OR(F22="",F22="متوفر ومكتمل"),"",IF(OR(C22="★",F22="غير متوفر"),"عالية","متوسطة"))
A23: 5-1-1 | D23: تشكيل اللجان والمجالس العاملة بالقسم بما يتضمن إشراك الجنسين والفروع (إن وجدت)، وكذا تمويل الأبحاث والمشاريع وحضور المؤتمرات. | E23: ='الخطة واللجنة'!$B$22 -> عضو 4 | H23: =IF(OR(F23="",F23="متوفر ومكتمل"),"",IF(OR(C23="★",F23="غير متوفر"),"عالية","متوسطة"))
A24: 6-1-1 | B24: تستفيد إدارة البرنامج من آراء المختصين والخبراء في تشكيل لجنة استشارية متنوعة الأعضاء وموضحة المهام، وتخصص البرنامج في تقييم وتطوير وتحسين أدائه. | D24: قرار تشكيل اللجنة الاستشارية للبرنامج المتنوعة الأعضاء والموضح مهامها. | E24: ='الخطة واللجنة'!$B$22 -> عضو 4 | H24: =IF(OR(F24="",F24="متوفر ومكتمل"),"",IF(OR(C24="★",F24="غير متوفر"),"عالية","متوسطة"))
A25: 6-1-1 | D25: نماذج من محاضر اللجنة الاستشارية للبرنامج متضمنة التوصيات وخطط تفعيلها. | E25: ='الخطة واللجنة'!$B$22 -> عضو 4 | H25: =IF(OR(F25="",F25="متوفر ومكتمل"),"",IF(OR(C25="★",F25="غير متوفر"),"عالية","متوسطة"))
A26: 6-1-1 | D26: تقرير استطلاع رأي جهات التوظيف حول الخريجين وتوصيات وخطط التحسين. | E26: ='الخطة واللجنة'!$B$22 -> عضو 4 | H26: =IF(OR(F26="",F26="متوفر ومكتمل"),"",IF(OR(C26="★",F26="غير متوفر"),"عالية","متوسطة"))
A27: 6-1-1 | D27: محاضر مجلس القسم متضمنة مناقشة توصيات اللجنة الاستشارية واستطلاع رأي جهات التوظيف وأي مقترحات تطوير من خبراء التخصص. | E27: ='الخطة واللجنة'!$B$22 -> عضو 4 | H27: =IF(OR(F27="",F27="متوفر ومكتمل"),"",IF(OR(C27="★",F27="غير متوفر"),"عالية","متوسطة"))
A28: 7-1-1 | B28: تتيح إدارة البرنامج معلومات موثوقة ومحدّثة تُبرز إنجازات البرنامج بما يتناسب مع احتياجات المستفيدين. | D28: الدليل التعريفي للبرنامج. | E28: ='الخطة واللجنة'!$B$22 -> عضو 4 | H28: =IF(OR(F28="",F28="متوفر ومكتمل"),"",IF(OR(C28="★",F28="غير متوفر"),"عالية","متوسطة"))
A29: 7-1-1 | D29: الموقع الإلكتروني للبرنامج متضمناً توصيف البرنامج والمقررات الدراسية وأنشطته وإنجازاته محدّثاً. | E29: ='الخطة واللجنة'!$B$22 -> عضو 4 | H29: =IF(OR(F29="",F29="متوفر ومكتمل"),"",IF(OR(C29="★",F29="غير متوفر"),"عالية","متوسطة"))
A30: 7-1-1 | D30: أنشطة لجنة خدمة المجتمع للتعريف بالبرنامج وإمكاناته والخدمات التي يقدمها للمجتمع. | E30: ='الخطة واللجنة'!$B$22 -> عضو 4 | H30: =IF(OR(F30="",F30="متوفر ومكتمل"),"",IF(OR(C30="★",F30="غير متوفر"),"عالية","متوسطة"))
A31: 7-1-1 | D31: نماذج من إعلانات ولقاءات التعريف بالبرنامج مع المستفيدين. | E31: ='الخطة واللجنة'!$B$22 -> عضو 4 | H31: =IF(OR(F31="",F31="متوفر ومكتمل"),"",IF(OR(C31="★",F31="غير متوفر"),"عالية","متوسطة"))
A32: 7-1-1 | D32: نتائج استطلاع رأي المستفيدين حول إتاحة المعلومات الخاصة بالبرنامج. | E32: ='الخطة واللجنة'!$B$22 -> عضو 4 | H32: =IF(OR(F32="",F32="متوفر ومكتمل"),"",IF(OR(C32="★",F32="غير متوفر"),"عالية","متوسطة"))
A33: 8-1-1 | B33: تلتزم إدارة البرنامج بتفعيل قيم الأمانة العلمية وحقوق الملكية الفكرية وقواعد الممارسات الأخلاقية والسلوك القويم في جميع المجالات والأنشطة الأكاديمية والبحثية والإدارية والخدمية. | C33: ★ | D33: السياسات والإجراءات الموثقة التي يطبقها البرنامج بشأن عمليات الاقتباس والملكية الفكرية للطلبة وأعضاء هيئة التدريس. | E33: ='الخطة واللجنة'!$B$22 -> عضو 4 | H33: =IF(OR(F33="",F33="متوفر ومكتمل"),"",IF(OR(C33="★",F33="غير متوفر"),"عالية","متوسطة"))
A34: 8-1-1 | C34: ★ | D34: دليل الإطار الأخلاقي للطلبة ومنسوبي الجامعة. | E34: ='الخطة واللجنة'!$B$22 -> عضو 4 | H34: =IF(OR(F34="",F34="متوفر ومكتمل"),"",IF(OR(C34="★",F34="غير متوفر"),"عالية","متوسطة"))
A35: 8-1-1 | C35: ★ | D35: دليل أخلاقيات البحث العلمي. | E35: ='الخطة واللجنة'!$B$22 -> عضو 4 | H35: =IF(OR(F35="",F35="متوفر ومكتمل"),"",IF(OR(C35="★",F35="غير متوفر"),"عالية","متوسطة"))
A36: 8-1-1 | C36: ★ | D36: قائمة بالدورات التدريبية المتعلقة بقيم الأمانة العلمية وحقوق الملكية الفكرية وقواعد الممارسات الأخلاقية. | E36: ='الخطة واللجنة'!$B$22 -> عضو 4 | H36: =IF(OR(F36="",F36="متوفر ومكتمل"),"",IF(OR(C36="★",F36="غير متوفر"),"عالية","متوسطة"))
A37: 8-1-1 | C37: ★ | D37: نماذج من تعميمات رئيس القسم على ضرورة الالتزام بقيم الأمانة العلمية وحقوق الملكية الفكرية. | E37: ='الخطة واللجنة'!$B$22 -> عضو 4 | H37: =IF(OR(F37="",F37="متوفر ومكتمل"),"",IF(OR(C37="★",F37="غير متوفر"),"عالية","متوسطة"))
A38: 8-1-1 | C38: ★ | D38: عينات من تقارير فحص الاستلال العلمي لأعمال الطلبة. | E38: ='الخطة واللجنة'!$B$22 -> عضو 4 | H38: =IF(OR(F38="",F38="متوفر ومكتمل"),"",IF(OR(C38="★",F38="غير متوفر"),"عالية","متوسطة"))
A39: 9-1-1 | B39: تتبنى إدارة البرنامج آلية واضحة وإجراءات معتمدة من قِبل المؤسسة/الكلية للشكاوى والتظلم والقضايا التأديبية. | D39: سياسات وآليات الشكاوى والتظلم المعتمدة سواء للطالب أو أعضاء هيئة التدريس. | E39: ='الخطة واللجنة'!$B$22 -> عضو 4 | H39: =IF(OR(F39="",F39="متوفر ومكتمل"),"",IF(OR(C39="★",F39="غير متوفر"),"عالية","متوسطة"))
A40: 9-1-1 | D40: نماذج من محاضر الرفع بالشكاوى والتظلمات وقرارات الرد عليها. | E40: ='الخطة واللجنة'!$B$22 -> عضو 4 | H40: =IF(OR(F40="",F40="متوفر ومكتمل"),"",IF(OR(C40="★",F40="غير متوفر"),"عالية","متوسطة"))
...
