Workbook

Sheet خطة العمل
A1: خطة المرحلة الأولى للاعتماد البرامجي: جمع الأدلة وتحديد الفجوات
A2: البرامج: بكالوريوس علوم الحاسب • بكالوريوس علوم البيانات • ماجستير علوم البيانات | المدة: 8 أسابيع | يبدأ الأسبوع 1 يوم الأحد 25 أكتوبر 2026
A4: الأسبوع | B4: المسار | C4: المهمة | D4: المسؤول | E4: المخرج | F4: الحالة | G4: ملاحظات
A5: الأسبوع 1 | B5: الأعضاء | C5: اجتماع الانطلاق مع اللجنة (الاثنين): شرح المعايير وأوراق الفحص وطريقة التقييم | D5: ='الإعدادات واللجنة'!$B$12 -> د. نهلة بنت سعد القثامي | E5: محضر الاجتماع | F5: لم تبدأ
A6: الأسبوع 1 | B6: الأعضاء | C6: عرض المقترح الخاص بمراجعة الرسالة والأهداف، وتحديد طريقة التنفيذ والمسؤول | D6: ='الإعدادات واللجنة'!$B$12 -> د. نهلة بنت سعد القثامي | E6: قرار اللجنة | F6: لم تبدأ
A7: الأسبوع 1 | B7: المتابعة والتنظيم | C7: وضع نظام ترميز الأدلة وتسميتها وهيكل مجلدات المستودع | D7: ='الإعدادات واللجنة'!$B$18 -> د. عبدالله بن محمد البركاتي | E7: دليل الترميز | F7: لم تبدأ
A8: الأسبوع 1 | B8: المتابعة والتنظيم | C8: إنشاء المستودع والملف المشترك وصلاحيات الأعضاء | D8: ='الإعدادات واللجنة'!$B$12 -> د. نهلة بنت سعد القثامي | E8: مستودع وملف مشترك جاهزان | F8: لم تبدأ
A9: الأسبوع 1 – 2 | B9: متطلبات الجودة | C9: اعتماد الأدلة المقترحة لمعيار البحث والمشاريع (6) في الماجستير | D9: ='الإعدادات واللجنة'!$B$13 -> د. عبير بنت عبدالله راجحي | E9: أدلة المعيار 6 معتمدة | F9: لم تبدأ
A10: الأسبوع 1 – 7 | B10: متطلبات الجودة | C10: متابعة متطلبات التقدم مع لجنة الجودة (انظر ورقة متطلبات التقدم للاعتماد) | D10: ='الإعدادات واللجنة'!$B$13 -> د. عبير بنت عبدالله راجحي | E10: حالة المتطلبات في الأسبوعين 4 و7 | F10: لم تبدأ
A11: الأسبوع 2 – 3 | B11: الأعضاء | C11: جمع الأدلة وتعبئة "حالة الدليل" و"سبب النقص" ورفع الأدلة بالترميز المعتمد | D11: كل عضو في معياره | E11: أوراق الفحص | F11: لم تبدأ
A12: الأسبوع 2 – 3 | B12: الأعضاء | C12: مراجعة الرسالة والأهداف حسب قرار اللجنة | D12: حسب قرار اللجنة | E12: أدلة المحك 1-1-1 | F12: لم تبدأ
A13: الأسبوع 2 – 6 | B13: المتابعة والتنظيم | C13: مراجعة أسبوعية لما رُفع من أدلة، ورسالة الخميس للجنة | D13: ='الإعدادات واللجنة'!$B$14 -> أ. فاطمة بنت سلمان الخزعل | E13: عمود المراجعة + رسالة أسبوعية | F13: لم تبدأ
A14: الأسبوع 4 | B14: الإدارة | C14: اجتماع منتصف الخطة: مراجعة لوحة المتابعة والعوائق، وعرض د. عبير لحالة متطلبات التقدم | D14: ='الإعدادات واللجنة'!$B$12 -> د. نهلة بنت سعد القثامي | E14: محضر | F14: لم تبدأ
A15: الأسبوع 4 – 5 | B15: الأعضاء | C15: استكمال جمع الأدلة وتقييم جودتها | D15: كل عضو في معياره | E15: أوراق الفحص | F15: لم تبدأ
A16: الأسبوع 6 | B16: الأعضاء | C16: إغلاق جمع الأدلة | D16: كل عضو في معياره | E16: كل الأدلة مُقيّمة | F16: لم تبدأ
A17: الأسبوع 6 | B17: الإدارة | C17: مراجعة كفاية أدلة المحكات الأساسية (14 للبكالوريوس و16 للماجستير) | D17: ='الإعدادات واللجنة'!$B$12 -> د. نهلة بنت سعد القثامي | E17: ملاحظات الرئيسة | F17: لم تبدأ
A18: الأسبوع 7 | B18: الأعضاء | C18: كتابة الإجراء المطلوب والموعد لكل دليل ناقص | D18: كل عضو في معياره | E18: خطة استكمال الأدلة | F18: لم تبدأ
A19: الأسبوع 7 | B19: الإدارة | C19: اجتماع مناقشة الفجوات وتمييز المشتركة بين البرامج، وعرض د. عبير لحالة متطلبات التقدم | D19: ='الإعدادات واللجنة'!$B$12 -> د. نهلة بنت سعد القثامي | E19: محضر | F19: لم تبدأ
A20: الأسبوع 7 | B20: المتابعة والتنظيم | C20: فهرس الأدلة النهائي لكل برنامج | D20: ='الإعدادات واللجنة'!$B$18 -> د. عبدالله بن محمد البركاتي | E20: 3 فهارس | F20: لم تبدأ
A21: الأسبوع 8 | B21: الإدارة | C21: إعداد تقرير الجاهزية لكل برنامج من لوحة المتابعة | D21: ='الإعدادات واللجنة'!$B$12&" + "&'الإعدادات واللجنة'!$B$14&" + "&'الإعدادات واللجنة'!$B$13 -> د. نهلة بنت سعد القثامي + أ. فاطمة بنت سلمان الخزعل + د. عبير بنت عبدالله راجحي | E21: 3 تقارير | F21: لم تبدأ
A22: الأسبوع 8 | B22: الإدارة | C22: اجتماع مع إدارة الكلية: عرض الجاهزية والفجوات وخطة المعالجة والقرارات المطلوبة | D22: ='الإعدادات واللجنة'!$B$12 -> د. نهلة بنت سعد القثامي | E22: قرار اعتماد خطة المعالجة | F22: لم تبدأ
A24: المتابعة (بدون اجتماع أسبوعي)
A25: • ملف مشترك (OneDrive / Google Drive): يعبّئ كل عضو ورقته مباشرة، ولوحة المتابعة تتحدث تلقائياً.
A26: • رسالة الخميس: ترسل أمينة اللجنة 3 أسطر في قروب اللجنة: نسبة الإنجاز لكل برنامج، ومن تأخر، وما يحتاج قراراً.
A27: • 3 اجتماعات للجنة عند المحطات: الانطلاق (الأسبوع 1)، ومنتصف الخطة (الأسبوع 4)، ومناقشة الفجوات (الأسبوع 7).
A29: طريقة تقييم الدليل
A30: • حالة الدليل: متوفر ومكتمل • متوفر ويحتاج تحسين • غير متوفر.
A31: • سبب النقص: غير معتمد • غير محدّث • لا يغطي المحك كاملاً • لا يثبت التطبيق الفعلي • لا توجد نتائج وتحسين.
A32: • الدليل "المكتمل": معتمد، ومحدّث، ويغطي المحك كاملاً، ويثبت التطبيق الفعلي، وفيه نتائج وتحسين.
A33: • الأولوية تلقائية: عالية إذا كان الدليل غير متوفر أو المحك أساسياً، ومتوسطة لبقية الناقص.
A34: • معالجة الفجوة تُكتب في سطر الدليل نفسه (الإجراء والموعد)، ولعرض الفجوات يُستخدم فلتر "حالة الدليل".
A35: • المراجعة: أمينة اللجنة تراجع كل الأدلة (الوجود، الرابط، الاعتماد والتاريخ، الترميز، المطابقة)، والرئيسة تراجع كفاية أدلة المحكات الأساسية.
A36: • الفترة الزمنية للأدلة: التقارير السنوية لآخر سنتين، ومؤشرات الأداء لآخر 3 سنوات.
... A44: • يُقيَّم وفق معايير الدراسات العليا 2022 (56 محكاً منها 16 أساسياً، ومعيار سادس للبحث والمشاريع). أدلة المحكات المشتركة مأخوذة من دليل البكالوريوس، وأدلة المعيار 6 مقترحة ومعلّمة باللون الأحمر وتعتمدها رئيسة الجودة. ترقيم المحكات موحّد بالترتيب المعتاد (مثل 1-1-2).

Sheet الإعدادات واللجنة
A1: الإعدادات وتشكيل لجنة الاعتماد البرامجي
A2: هذه الصفحة هي المكان الوحيد لتعديل الأسماء: أي تعديل في الخلايا الصفراء يتحدث تلقائياً في الخطة وأوراق الفحص ولوحة المتابعة.
A4: البرامج
A5: البرنامج 1 | B5: بكالوريوس علوم الحاسب
A6: البرنامج 2 | B6: بكالوريوس علوم البيانات
A7: البرنامج 3 | B7: ماجستير علوم البيانات
A8: يبدأ الأسبوع 1 يوم الأحد 25 أكتوبر 2026 – مدة الخطة 8 أسابيع.
A10: أعضاء اللجنة
A11: م | B11: الاسم | C11: الدور | D11: المسؤولية | E11: عدد الأدلة المسندة
A12: 1 | B12: د. نهلة بنت سعد القثامي | C12: رئيسة اللجنة | D12: القيادة والمتابعة، واعتماد المخرجات، ومراجعة كفاية أدلة المعايير الأساسية (14 للبكالوريوس و16 للماجستير)، والتواصل مع إدارة الكلية | E12: =COUNTIF('فحص-حاسب-بكالوريوس'!$H:$H,B12)+COUNTIF('فحص-بيانات-بكالوريوس'!$H:$H,B12)+COUNTIF('فحص-بيانات-ماجستير'!$H:$H,B12) -> 0
A13: 2 | B13: د. عبير بنت عبدالله راجحي | C13: رئيسة الجودة | D13: متطلبات التقدم مع لجنة الجودة (التوصيفات، والتقارير السنوية، والإطار الوطني، ونواتج التعلم، ومؤشرات الأداء) وعرض حالتها في الأسبوعين 4 و7؛ واعتماد الأدلة المقترحة لمعيار البحث في الماجستير | E13: =COUNTIF('فحص-حاسب-بكالوريوس'!$H:$H,B13)+COUNTIF('فحص-بيانات-بكالوريوس'!$H:$H,B13)+COUNTIF('فحص-بيانات-ماجستير'!$H:$H,B13) -> 0
A14: 3 | B14: أ. فاطمة بنت سلمان الخزعل | C14: أمينة اللجنة والمراجِعة | D14: مراجعة جميع الأدلة أسبوعياً (الوجود، الرابط، الاعتماد والتاريخ، الترميز، المطابقة للمحك)، ولوحة المتابعة، ورسالة الخميس، والمحاضر | E14: =COUNTIF('فحص-حاسب-بكالوريوس'!$H:$H,B14)+COUNTIF('فحص-بيانات-بكالوريوس'!$H:$H,B14)+COUNTIF('فحص-بيانات-ماجستير'!$H:$H,B14) -> 0
A15: 4 | B15: د. سلطان بن سعيد الشمراني | C15: عضو | D15: المعيار 1: إدارة البرنامج (1-1) للبرامج الثلاثة | E15: =COUNTIF('فحص-حاسب-بكالوريوس'!$H:$H,B15)+COUNTIF('فحص-بيانات-بكالوريوس'!$H:$H,B15)+COUNTIF('فحص-بيانات-ماجستير'!$H:$H,B15) -> 117
A16: 5 | B16: د. احمد بن عوض البشري | C16: عضو | D16: المعيار 2: نواتج التعلم والمنهج الدراسي (2-1، 2-2) للبرامج الثلاثة | E16: =COUNTIF('فحص-حاسب-بكالوريوس'!$H:$H,B16)+COUNTIF('فحص-بيانات-بكالوريوس'!$H:$H,B16)+COUNTIF('فحص-بيانات-ماجستير'!$H:$H,B16) -> 141
A17: 6 | B17: د. يثرب بنت سعد القحطاني | C17: عضو | D17: المعيار 2: جودة التدريس وتقييم الطالب (2-3) للبرامج الثلاثة | E17: =COUNTIF('فحص-حاسب-بكالوريوس'!$H:$H,B17)+COUNTIF('فحص-بيانات-بكالوريوس'!$H:$H,B17)+COUNTIF('فحص-بيانات-ماجستير'!$H:$H,B17) -> 77
A18: 7 | B18: د. عبدالله بن محمد البركاتي | C18: عضو + مسؤول الفهرسة | D18: المعيار 3: الطالب للبرامج الثلاثة، ونظام ترميز الأدلة وفهرستها وفهرس الأدلة النهائي | E18: =COUNTIF('فحص-حاسب-بكالوريوس'!$H:$H,B18)+COUNTIF('فحص-بيانات-بكالوريوس'!$H:$H,B18)+COUNTIF('فحص-بيانات-ماجستير'!$H:$H,B18) -> 92
A19: 8 | B19: د. عمر بن محمد موسى | C19: عضو | D19: المعيار 4: هيئة التدريس للبرامج الثلاثة، والمعيار 6: البحث والمشاريع للماجستير | E19: =COUNTIF('فحص-حاسب-بكالوريوس'!$H:$H,B19)+COUNTIF('فحص-بيانات-بكالوريوس'!$H:$H,B19)+COUNTIF('فحص-بيانات-ماجستير'!$H:$H,B19) -> 111
A20: 9 | B20: د. حسن بن سعد القحطاني | C20: عضو | D20: المعيار 5: مصادر التعلم والمرافق، ومحور ضمان الجودة (1-2) للبرامج الثلاثة | E20: =COUNTIF('فحص-حاسب-بكالوريوس'!$H:$H,B20)+COUNTIF('فحص-بيانات-بكالوريوس'!$H:$H,B20)+COUNTIF('فحص-بيانات-ماجستير'!$H:$H,B20) -> 96
A22: توزيع المحاور (المسؤول عن المحور للبرامج الثلاثة) – يمكن تغيير المسؤول من القائمة المنسدلة
A23: الرمز | B23: المحور | C23: المسؤول | D23: عدد المحكات (البرامج الثلاثة) | E23: عدد الأدلة (البرامج الثلاثة)
A24: 1-1 | B24: إدارة البرنامج | C24: ='الإعدادات واللجنة'!$B$15 -> د. سلطان بن سعيد الشمراني | D24: =COUNTIFS('فحص-حاسب-بكالوريوس'!$A:$A,A24&"-*",'فحص-حاسب-بكالوريوس'!$C:$C,"<>")+COUNTIFS('فحص-بيانات-بكالوريوس'!$A:$A,A24&"-*",'فحص-بيانات-بكالوريوس'!$C:$C,"<>")+COUNTIFS('فحص-بيانات-ماجستير'!$A:$A,A24&"-*",'فحص-بيانات-ماجستير'!$C:$C,"<>") -> 27 | E24: =COUNTIF('فحص-حاسب-بكالوريوس'!$A:$A,A24&"-*")+COUNTIF('فحص-بيانات-بكالوريوس'!$A:$A,A24&"-*")+COUNTIF('فحص-بيانات-ماجستير'!$A:$A,A24&"-*") -> 117
A25: 1-2 | B25: ضمان جودة البرنامج | C25: ='الإعدادات واللجنة'!$B$20 -> د. حسن بن سعد القحطاني | D25: =COUNTIFS('فحص-حاسب-بكالوريوس'!$A:$A,A25&"-*",'فحص-حاسب-بكالوريوس'!$C:$C,"<>")+COUNTIFS('فحص-بيانات-بكالوريوس'!$A:$A,A25&"-*",'فحص-بيانات-بكالوريوس'!$C:$C,"<>")+COUNTIFS('فحص-بيانات-ماجستير'!$A:$A,A25&"-*",'فحص-بيانات-ماجستير'!$C:$C,"<>") -> 9 | E25: =COUNTIF('فحص-حاسب-بكالوريوس'!$A:$A,A25&"-*")+COUNTIF('فحص-بيانات-بكالوريوس'!$A:$A,A25&"-*")+COUNTIF('فحص-بيانات-ماجستير'!$A:$A,A25&"-*") -> 39
A26: 2-1 | B26: نواتج التعلم | C26: ='الإعدادات واللجنة'!$B$16 -> د. احمد بن عوض البشري | D26: =COUNTIFS('فحص-حاسب-بكالوريوس'!$A:$A,A26&"-*",'فحص-حاسب-بكالوريوس'!$C:$C,"<>")+COUNTIFS('فحص-بيانات-بكالوريوس'!$A:$A,A26&"-*",'فحص-بيانات-بكالوريوس'!$C:$C,"<>")+COUNTIFS('فحص-بيانات-ماجستير'!$A:$A,A26&"-*",'فحص-بيانات-ماجستير'!$C:$C,"<>") -> 15 | E26: =COUNTIF('فحص-حاسب-بكالوريوس'!$A:$A,A26&"-*")+COUNTIF('فحص-بيانات-بكالوريوس'!$A:$A,A26&"-*")+COUNTIF('فحص-بيانات-ماجستير'!$A:$A,A26&"-*") -> 75
A27: 2-2 | B27: المنهج الدراسي | C27: ='الإعدادات واللجنة'!$B$16 -> د. احمد بن عوض البشري | D27: =COUNTIFS('فحص-حاسب-بكالوريوس'!$A:$A,A27&"-*",'فحص-حاسب-بكالوريوس'!$C:$C,"<>")+COUNTIFS('فحص-بيانات-بكالوريوس'!$A:$A,A27&"-*",'فحص-بيانات-بكالوريوس'!$C:$C,"<>")+COUNTIFS('فحص-بيانات-ماجستير'!$A:$A,A27&"-*",'فحص-بيانات-ماجستير'!$C:$C,"<>") -> 18 | E27: =COUNTIF('فحص-حاسب-بكالوريوس'!$A:$A,A27&"-*")+COUNTIF('فحص-بيانات-بكالوريوس'!$A:$A,A27&"-*")+COUNTIF('فحص-بيانات-ماجستير'!$A:$A,A27&"-*") -> 66
A28: 2-3 | B28: جودة التدريس وتقييم الطالب | C28: ='الإعدادات واللجنة'!$B$17 -> د. يثرب بنت سعد القحطاني | D28: =COUNTIFS('فحص-حاسب-بكالوريوس'!$A:$A,A28&"-*",'فحص-حاسب-بكالوريوس'!$C:$C,"<>")+COUNTIFS('فحص-بيانات-بكالوريوس'!$A:$A,A28&"-*",'فحص-بيانات-بكالوريوس'!$C:$C,"<>")+COUNTIFS('فحص-بيانات-ماجستير'!$A:$A,A28&"-*",'فحص-بيانات-ماجستير'!$C:$C,"<>") -> 19 | E28: =COUNTIF('فحص-حاسب-بكالوريوس'!$A:$A,A28&"-*")+COUNTIF('فحص-بيانات-بكالوريوس'!$A:$A,A28&"-*")+COUNTIF('فحص-بيانات-ماجستير'!$A:$A,A28&"-*") -> 77
A29: 3-0 | B29: الطالب | C29: ='الإعدادات واللجنة'!$B$18 -> د. عبدالله بن محمد البركاتي | D29: =COUNTIFS('فحص-حاسب-بكالوريوس'!$A:$A,A29&"-*",'فحص-حاسب-بكالوريوس'!$C:$C,"<>")+COUNTIFS('فحص-بيانات-بكالوريوس'!$A:$A,A29&"-*",'فحص-بيانات-بكالوريوس'!$C:$C,"<>")+COUNTIFS('فحص-بيانات-ماجستير'!$A:$A,A29&"-*",'فحص-بيانات-ماجستير'!$C:$C,"<>") -> 20 | E29: =COUNTIF('فحص-حاسب-بكالوريوس'!$A:$A,A29&"-*")+COUNTIF('فحص-بيانات-بكالوريوس'!$A:$A,A29&"-*")+COUNTIF('فحص-بيانات-ماجستير'!$A:$A,A29&"-*") -> 92
A30: 4-0 | B30: هيئة التدريس | C30: ='الإعدادات واللجنة'!$B$19 -> د. عمر بن محمد موسى | D30: =COUNTIFS('فحص-حاسب-بكالوريوس'!$A:$A,A30&"-*",'فحص-حاسب-بكالوريوس'!$C:$C,"<>")+COUNTIFS('فحص-بيانات-بكالوريوس'!$A:$A,A30&"-*",'فحص-بيانات-بكالوريوس'!$C:$C,"<>")+COUNTIFS('فحص-بيانات-ماجستير'!$A:$A,A30&"-*",'فحص-بيانات-ماجستير'!$C:$C,"<>") -> 18 | E30: =COUNTIF('فحص-حاسب-بكالوريوس'!$A:$A,A30&"-*")+COUNTIF('فحص-بيانات-بكالوريوس'!$A:$A,A30&"-*")+COUNTIF('فحص-بيانات-ماجستير'!$A:$A,A30&"-*") -> 78
A31: 5-0 | B31: مصادر التعلم والمرافق والتجهيزات | C31: ='الإعدادات واللجنة'!$B$20 -> د. حسن بن سعد القحطاني | D31: =COUNTIFS('فحص-حاسب-بكالوريوس'!$A:$A,A31&"-*",'فحص-حاسب-بكالوريوس'!$C:$C,"<>")+COUNTIFS('فحص-بيانات-بكالوريوس'!$A:$A,A31&"-*",'فحص-بيانات-بكالوريوس'!$C:$C,"<>")+COUNTIFS('فحص-بيانات-ماجستير'!$A:$A,A31&"-*",'فحص-بيانات-ماجستير'!$C:$C,"<>") -> 15 | E31: =COUNTIF('فحص-حاسب-بكالوريوس'!$A:$A,A31&"-*")+COUNTIF('فحص-بيانات-بكالوريوس'!$A:$A,A31&"-*")+COUNTIF('فحص-بيانات-ماجستير'!$A:$A,A31&"-*") -> 57
A32: 6-0 | B32: البحث والمشاريع (ماجستير فقط) | C32: ='الإعدادات واللجنة'!$B$19 -> د. عمر بن محمد موسى | D32: =COUNTIFS('فحص-حاسب-بكالوريوس'!$A:$A,A32&"-*",'فحص-حاسب-بكالوريوس'!$C:$C,"<>")+COUNTIFS('فحص-بيانات-بكالوريوس'!$A:$A,A32&"-*",'فحص-بيانات-بكالوريوس'!$C:$C,"<>")+COUNTIFS('فحص-بيانات-ماجستير'!$A:$A,A32&"-*",'فحص-بيانات-ماجستير'!$C:$C,"<>") -> 11 | E32: =COUNTIF('فحص-حاسب-بكالوريوس'!$A:$A,A32&"-*")+COUNTIF('فحص-بيانات-بكالوريوس'!$A:$A,A32&"-*")+COUNTIF('فحص-بيانات-ماجستير'!$A:$A,A32&"-*") -> 33

Sheet لوحة المتابعة
A1: لوحة المتابعة (تتحدث تلقائياً)
A2: نسبة الاكتمال = الأدلة المتوفرة والمكتملة ÷ إجمالي الأدلة. تُستخدم هذه الصفحة لرسالة الخميس وتقرير الأسبوع 8.
A4: ='الإعدادات واللجنة'!$B$5 -> بكالوريوس علوم الحاسب
A5: المعيار | B5: عدد الأدلة | C5: مكتمل | D5: يحتاج تحسين | E5: غير متوفر | F5: لم يُقيَّم | G5: نسبة الاكتمال | H5: أولوية عالية | I5: راجعتها أ. فاطمة
A6: 1. إدارة البرنامج وضمان جودته | B6: =COUNTIF('فحص-حاسب-بكالوريوس'!$B$5:$B$208,"1. إدارة البرنامج وضمان جودته") -> 52 | C6: =COUNTIFS('فحص-حاسب-بكالوريوس'!$B$5:$B$208,"1. إدارة البرنامج وضمان جودته",'فحص-حاسب-بكالوريوس'!$I$5:$I$208,"متوفر ومكتمل") -> 0 | D6: =COUNTIFS('فحص-حاسب-بكالوريوس'!$B$5:$B$208,"1. إدارة البرنامج وضمان جودته",'فحص-حاسب-بكالوريوس'!$I$5:$I$208,"متوفر ويحتاج تحسين") -> 0 | E6: =COUNTIFS('فحص-حاسب-بكالوريوس'!$B$5:$B$208,"1. إدارة البرنامج وضمان جودته",'فحص-حاسب-بكالوريوس'!$I$5:$I$208,"غير متوفر") -> 0 | F6: =B6-SUM(C6:E6) -> 52 | G6: =IF(B6=0,0,C6/B6) -> 0 | H6: =COUNTIFS('فحص-حاسب-بكالوريوس'!$B$5:$B$208,"1. إدارة البرنامج وضمان جودته",'فحص-حاسب-بكالوريوس'!$K$5:$K$208,"عالية") -> 0 | I6: =COUNTIFS('فحص-حاسب-بكالوريوس'!$B$5:$B$208,"1. إدارة البرنامج وضمان جودته",'فحص-حاسب-بكالوريوس'!$P$5:$P$208,"<>") -> 0
A7: 2. التعليم والتعلم | B7: =COUNTIF('فحص-حاسب-بكالوريوس'!$B$5:$B$208,"2. التعليم والتعلم") -> 75 | C7: =COUNTIFS('فحص-حاسب-بكالوريوس'!$B$5:$B$208,"2. التعليم والتعلم",'فحص-حاسب-بكالوريوس'!$I$5:$I$208,"متوفر ومكتمل") -> 0 | D7: =COUNTIFS('فحص-حاسب-بكالوريوس'!$B$5:$B$208,"2. التعليم والتعلم",'فحص-حاسب-بكالوريوس'!$I$5:$I$208,"متوفر ويحتاج تحسين") -> 0 | E7: =COUNTIFS('فحص-حاسب-بكالوريوس'!$B$5:$B$208,"2. التعليم والتعلم",'فحص-حاسب-بكالوريوس'!$I$5:$I$208,"غير متوفر") -> 0 | F7: =B7-SUM(C7:E7) -> 75 | G7: =IF(B7=0,0,C7/B7) -> 0 | H7: =COUNTIFS('فحص-حاسب-بكالوريوس'!$B$5:$B$208,"2. التعليم والتعلم",'فحص-حاسب-بكالوريوس'!$K$5:$K$208,"عالية") -> 0 | I7: =COUNTIFS('فحص-حاسب-بكالوريوس'!$B$5:$B$208,"2. التعليم والتعلم",'فحص-حاسب-بكالوريوس'!$P$5:$P$208,"<>") -> 0
A8: 3. الطالب | B8: =COUNTIF('فحص-حاسب-بكالوريوس'!$B$5:$B$208,"3. الطالب") -> 32 | C8: =COUNTIFS('فحص-حاسب-بكالوريوس'!$B$5:$B$208,"3. الطالب",'فحص-حاسب-بكالوريوس'!$I$5:$I$208,"متوفر ومكتمل") -> 0 | D8: =COUNTIFS('فحص-حاسب-بكالوريوس'!$B$5:$B$208,"3. الطالب",'فحص-حاسب-بكالوريوس'!$I$5:$I$208,"متوفر ويحتاج تحسين") -> 0 | E8: =COUNTIFS('فحص-حاسب-بكالوريوس'!$B$5:$B$208,"3. الطالب",'فحص-حاسب-بكالوريوس'!$I$5:$I$208,"غير متوفر") -> 0 | F8: =B8-SUM(C8:E8) -> 32 | G8: =IF(B8=0,0,C8/B8) -> 0 | H8: =COUNTIFS('فحص-حاسب-بكالوريوس'!$B$5:$B$208,"3. الطالب",'فحص-حاسب-بكالوريوس'!$K$5:$K$208,"عالية") -> 0 | I8: =COUNTIFS('فحص-حاسب-بكالوريوس'!$B$5:$B$208,"3. الطالب",'فحص-حاسب-بكالوريوس'!$P$5:$P$208,"<>") -> 0
A9: 4. هيئة التدريس | B9: =COUNTIF('فحص-حاسب-بكالوريوس'!$B$5:$B$208,"4. هيئة التدريس") -> 26 | C9: =COUNTIFS('فحص-حاسب-بكالوريوس'!$B$5:$B$208,"4. هيئة التدريس",'فحص-حاسب-بكالوريوس'!$I$5:$I$208,"متوفر ومكتمل") -> 0 | D9: =COUNTIFS('فحص-حاسب-بكالوريوس'!$B$5:$B$208,"4. هيئة التدريس",'فحص-حاسب-بكالوريوس'!$I$5:$I$208,"متوفر ويحتاج تحسين") -> 0 | E9: =COUNTIFS('فحص-حاسب-بكالوريوس'!$B$5:$B$208,"4. هيئة التدريس",'فحص-حاسب-بكالوريوس'!$I$5:$I$208,"غير متوفر") -> 0 | F9: =B9-SUM(C9:E9) -> 26 | G9: =IF(B9=0,0,C9/B9) -> 0 | H9: =COUNTIFS('فحص-حاسب-بكالوريوس'!$B$5:$B$208,"4. هيئة التدريس",'فحص-حاسب-بكالوريوس'!$K$5:$K$208,"عالية") -> 0 | I9: =COUNTIFS('فحص-حاسب-بكالوريوس'!$B$5:$B$208,"4. هيئة التدريس",'فحص-حاسب-بكالوريوس'!$P$5:$P$208,"<>") -> 0
A10: 5. مصادر التعلم والمرافق والتجهيزات | B10: =COUNTIF('فحص-حاسب-بكالوريوس'!$B$5:$B$208,"5. مصادر التعلم والمرافق والتجهيزات") -> 19 | C10: =COUNTIFS('فحص-حاسب-بكالوريوس'!$B$5:$B$208,"5. مصادر التعلم والمرافق والتجهيزات",'فحص-حاسب-بكالوريوس'!$I$5:$I$208,"متوفر ومكتمل") -> 0 | D10: =COUNTIFS('فحص-حاسب-بكالوريوس'!$B$5:$B$208,"5. مصادر التعلم والمرافق والتجهيزات",'فحص-حاسب-بكالوريوس'!$I$5:$I$208,"متوفر ويحتاج تحسين") -> 0 | E10: =COUNTIFS('فحص-حاسب-بكالوريوس'!$B$5:$B$208,"5. مصادر التعلم والمرافق والتجهيزات",'فحص-حاسب-بكالوريوس'!$I$5:$I$208,"غير متوفر") -> 0 | F10: =B10-SUM(C10:E10) -> 19 | G10: =IF(B10=0,0,C10/B10) -> 0 | H10: =COUNTIFS('فحص-حاسب-بكالوريوس'!$B$5:$B$208,"5. مصادر التعلم والمرافق والتجهيزات",'فحص-حاسب-بكالوريوس'!$K$5:$K$208,"عالية") -> 0 | I10: =COUNTIFS('فحص-حاسب-بكالوريوس'!$B$5:$B$208,"5. مصادر التعلم والمرافق والتجهيزات",'فحص-حاسب-بكالوريوس'!$P$5:$P$208,"<>") -> 0
A11: المحكات الأساسية ★ | B11: =COUNTIF('فحص-حاسب-بكالوريوس'!$D$5:$D$208,"★") -> 63 | C11: =COUNTIFS('فحص-حاسب-بكالوريوس'!$D$5:$D$208,"★",'فحص-حاسب-بكالوريوس'!$I$5:$I$208,"متوفر ومكتمل") -> 0 | D11: =COUNTIFS('فحص-حاسب-بكالوريوس'!$D$5:$D$208,"★",'فحص-حاسب-بكالوريوس'!$I$5:$I$208,"متوفر ويحتاج تحسين") -> 0 | E11: =COUNTIFS('فحص-حاسب-بكالوريوس'!$D$5:$D$208,"★",'فحص-حاسب-بكالوريوس'!$I$5:$I$208,"غير متوفر") -> 0 | F11: =B11-SUM(C11:E11) -> 63 | G11: =IF(B11=0,0,C11/B11) -> 0 | H11: =COUNTIFS('فحص-حاسب-بكالوريوس'!$D$5:$D$208,"★",'فحص-حاسب-بكالوريوس'!$K$5:$K$208,"عالية") -> 0 | I11: =COUNTIFS('فحص-حاسب-بكالوريوس'!$D$5:$D$208,"★",'فحص-حاسب-بكالوريوس'!$P$5:$P$208,"<>") -> 0
A12: الإجمالي | B12: =COUNTIF('فحص-حاسب-بكالوريوس'!$A$5:$A$208,"*") -> 204 | C12: =COUNTIFS('فحص-حاسب-بكالوريوس'!$A$5:$A$208,"*",'فحص-حاسب-بكالوريوس'!$I$5:$I$208,"متوفر ومكتمل") -> 0 | D12: =COUNTIFS('فحص-حاسب-بكالوريوس'!$A$5:$A$208,"*",'فحص-حاسب-بكالوريوس'!$I$5:$I$208,"متوفر ويحتاج تحسين") -> 0 | E12: =COUNTIFS('فحص-حاسب-بكالوريوس'!$A$5:$A$208,"*",'فحص-حاسب-بكالوريوس'!$I$5:$I$208,"غير متوفر") -> 0 | F12: =B12-SUM(C12:E12) -> 204 | G12: =IF(B12=0,0,C12/B12) -> 0 | H12: =COUNTIFS('فحص-حاسب-بكالوريوس'!$A$5:$A$208,"*",'فحص-حاسب-بكالوريوس'!$K$5:$K$208,"عالية") -> 0 | I12: =COUNTIFS('فحص-حاسب-بكالوريوس'!$A$5:$A$208,"*",'فحص-حاسب-بكالوريوس'!$P$5:$P$208,"<>") -> 0
A14: ='الإعدادات واللجنة'!$B$6 -> بكالوريوس علوم البيانات
A15: المعيار | B15: عدد الأدلة | C15: مكتمل | D15: يحتاج تحسين | E15: غير متوفر | F15: لم يُقيَّم | G15: نسبة الاكتمال | H15: أولوية عالية | I15: راجعتها أ. فاطمة
A16: 1. إدارة البرنامج وضمان جودته | B16: =COUNTIF('فحص-بيانات-بكالوريوس'!$B$5:$B$208,"1. إدارة البرنامج وضمان جودته") -> 52 | C16: =COUNTIFS('فحص-بيانات-بكالوريوس'!$B$5:$B$208,"1. إدارة البرنامج وضمان جودته",'فحص-بيانات-بكالوريوس'!$I$5:$I$208,"متوفر ومكتمل") -> 0 | D16: =COUNTIFS('فحص-بيانات-بكالوريوس'!$B$5:$B$208,"1. إدارة البرنامج وضمان جودته",'فحص-بيانات-بكالوريوس'!$I$5:$I$208,"متوفر ويحتاج تحسين") -> 0 | E16: =COUNTIFS('فحص-بيانات-بكالوريوس'!$B$5:$B$208,"1. إدارة البرنامج وضمان جودته",'فحص-بيانات-بكالوريوس'!$I$5:$I$208,"غير متوفر") -> 0 | F16: =B16-SUM(C16:E16) -> 52 | G16: =IF(B16=0,0,C16/B16) -> 0 | H16: =COUNTIFS('فحص-بيانات-بكالوريوس'!$B$5:$B$208,"1. إدارة البرنامج وضمان جودته",'فحص-بيانات-بكالوريوس'!$K$5:$K$208,"عالية") -> 0 | I16: =COUNTIFS('فحص-بيانات-بكالوريوس'!$B$5:$B$208,"1. إدارة البرنامج وضمان جودته",'فحص-بيانات-بكالوريوس'!$P$5:$P$208,"<>") -> 0
A17: 2. التعليم والتعلم | B17: =COUNTIF('فحص-بيانات-بكالوريوس'!$B$5:$B$208,"2. التعليم والتعلم") -> 75 | C17: =COUNTIFS('فحص-بيانات-بكالوريوس'!$B$5:$B$208,"2. التعليم والتعلم",'فحص-بيانات-بكالوريوس'!$I$5:$I$208,"متوفر ومكتمل") -> 0 | D17: =COUNTIFS('فحص-بيانات-بكالوريوس'!$B$5:$B$208,"2. التعليم والتعلم",'فحص-بيانات-بكالوريوس'!$I$5:$I$208,"متوفر ويحتاج تحسين") -> 0 | E17: =COUNTIFS('فحص-بيانات-بكالوريوس'!$B$5:$B$208,"2. التعليم والتعلم",'فحص-بيانات-بكالوريوس'!$I$5:$I$208,"غير متوفر") -> 0 | F17: =B17-SUM(C17:E17) -> 75 | G17: =IF(B17=0,0,C17/B17) -> 0 | H17: =COUNTIFS('فحص-بيانات-بكالوريوس'!$B$5:$B$208,"2. التعليم والتعلم",'فحص-بيانات-بكالوريوس'!$K$5:$K$208,"عالية") -> 0 | I17: =COUNTIFS('فحص-بيانات-بكالوريوس'!$B$5:$B$208,"2. التعليم والتعلم",'فحص-بيانات-بكالوريوس'!$P$5:$P$208,"<>") -> 0
A18: 3. الطالب | B18: =COUNTIF('فحص-بيانات-بكالوريوس'!$B$5:$B$208,"3. الطالب") -> 32 | C18: =COUNTIFS('فحص-بيانات-بكالوريوس'!$B$5:$B$208,"3. الطالب",'فحص-بيانات-بكالوريوس'!$I$5:$I$208,"متوفر ومكتمل") -> 0 | D18: =COUNTIFS('فحص-بيانات-بكالوريوس'!$B$5:$B$208,"3. الطالب",'فحص-بيانات-بكالوريوس'!$I$5:$I$208,"متوفر ويحتاج تحسين") -> 0 | E18: =COUNTIFS('فحص-بيانات-بكالوريوس'!$B$5:$B$208,"3. الطالب",'فحص-بيانات-بكالوريوس'!$I$5:$I$208,"غير متوفر") -> 0 | F18: =B18-SUM(C18:E18) -> 32 | G18: =IF(B18=0,0,C18/B18) -> 0 | H18: =COUNTIFS('فحص-بيانات-بكالوريوس'!$B$5:$B$208,"3. الطالب",'فحص-بيانات-بكالوريوس'!$K$5:$K$208,"عالية") -> 0 | I18: =COUNTIFS('فحص-بيانات-بكالوريوس'!$B$5:$B$208,"3. الطالب",'فحص-بيانات-بكالوريوس'!$P$5:$P$208,"<>") -> 0
A19: 4. هيئة التدريس | B19: =COUNTIF('فحص-بيانات-بكالوريوس'!$B$5:$B$208,"4. هيئة التدريس") -> 26 | C19: =COUNTIFS('فحص-بيانات-بكالوريوس'!$B$5:$B$208,"4. هيئة التدريس",'فحص-بيانات-بكالوريوس'!$I$5:$I$208,"متوفر ومكتمل") -> 0 | D19: =COUNTIFS('فحص-بيانات-بكالوريوس'!$B$5:$B$208,"4. هيئة التدريس",'فحص-بيانات-بكالوريوس'!$I$5:$I$208,"متوفر ويحتاج تحسين") -> 0 | E19: =COUNTIFS('فحص-بيانات-بكالوريوس'!$B$5:$B$208,"4. هيئة التدريس",'فحص-بيانات-بكالوريوس'!$I$5:$I$208,"غير متوفر") -> 0 | F19: =B19-SUM(C19:E19) -> 26 | G19: =IF(B19=0,0,C19/B19) -> 0 | H19: =COUNTIFS('فحص-بيانات-بكالوريوس'!$B$5:$B$208,"4. هيئة التدريس",'فحص-بيانات-بكالوريوس'!$K$5:$K$208,"عالية") -> 0 | I19: =COUNTIFS('فحص-بيانات-بكالوريوس'!$B$5:$B$208,"4. هيئة التدريس",'فحص-بيانات-بكالوريوس'!$P$5:$P$208,"<>") -> 0
A20: 5. مصادر التعلم والمرافق والتجهيزات | B20: =COUNTIF('فحص-بيانات-بكالوريوس'!$B$5:$B$208,"5. مصادر التعلم والمرافق والتجهيزات") -> 19 | C20: =COUNTIFS('فحص-بيانات-بكالوريوس'!$B$5:$B$208,"5. مصادر التعلم والمرافق والتجهيزات",'فحص-بيانات-بكالوريوس'!$I$5:$I$208,"متوفر ومكتمل") -> 0 | D20: =COUNTIFS('فحص-بيانات-بكالوريوس'!$B$5:$B$208,"5. مصادر التعلم والمرافق والتجهيزات",'فحص-بيانات-بكالوريوس'!$I$5:$I$208,"متوفر ويحتاج تحسين") -> 0 | E20: =COUNTIFS('فحص-بيانات-بكالوريوس'!$B$5:$B$208,"5. مصادر التعلم والمرافق والتجهيزات",'فحص-بيانات-بكالوريوس'!$I$5:$I$208,"غير متوفر") -> 0 | F20: =B20-SUM(C20:E20) -> 19 | G20: =IF(B20=0,0,C20/B20) -> 0 | H20: =COUNTIFS('فحص-بيانات-بكالوريوس'!$B$5:$B$208,"5. مصادر التعلم والمرافق والتجهيزات",'فحص-بيانات-بكالوريوس'!$K$5:$K$208,"عالية") -> 0 | I20: =COUNTIFS('فحص-بيانات-بكالوريوس'!$B$5:$B$208,"5. مصادر التعلم والمرافق والتجهيزات",'فحص-بيانات-بكالوريوس'!$P$5:$P$208,"<>") -> 0
A21: المحكات الأساسية ★ | B21: =COUNTIF('فحص-بيانات-بكالوريوس'!$D$5:$D$208,"★") -> 63 | C21: =COUNTIFS('فحص-بيانات-بكالوريوس'!$D$5:$D$208,"★",'فحص-بيانات-بكالوريوس'!$I$5:$I$208,"متوفر ومكتمل") -> 0 | D21: =COUNTIFS('فحص-بيانات-بكالوريوس'!$D$5:$D$208,"★",'فحص-بيانات-بكالوريوس'!$I$5:$I$208,"متوفر ويحتاج تحسين") -> 0 | E21: =COUNTIFS('فحص-بيانات-بكالوريوس'!$D$5:$D$208,"★",'فحص-بيانات-بكالوريوس'!$I$5:$I$208,"غير متوفر") -> 0 | F21: =B21-SUM(C21:E21) -> 63 | G21: =IF(B21=0,0,C21/B21) -> 0 | H21: =COUNTIFS('فحص-بيانات-بكالوريوس'!$D$5:$D$208,"★",'فحص-بيانات-بكالوريوس'!$K$5:$K$208,"عالية") -> 0 | I21: =COUNTIFS('فحص-بيانات-بكالوريوس'!$D$5:$D$208,"★",'فحص-بيانات-بكالوريوس'!$P$5:$P$208,"<>") -> 0
A22: الإجمالي | B22: =COUNTIF('فحص-بيانات-بكالوريوس'!$A$5:$A$208,"*") -> 204 | C22: =COUNTIFS('فحص-بيانات-بكالوريوس'!$A$5:$A$208,"*",'فحص-بيانات-بكالوريوس'!$I$5:$I$208,"متوفر ومكتمل") -> 0 | D22: =COUNTIFS('فحص-بيانات-بكالوريوس'!$A$5:$A$208,"*",'فحص-بيانات-بكالوريوس'!$I$5:$I$208,"متوفر ويحتاج تحسين") -> 0 | E22: =COUNTIFS('فحص-بيانات-بكالوريوس'!$A$5:$A$208,"*",'فحص-بيانات-بكالوريوس'!$I$5:$I$208,"غير متوفر") -> 0 | F22: =B22-SUM(C22:E22) -> 204 | G22: =IF(B22=0,0,C22/B22) -> 0 | H22: =COUNTIFS('فحص-بيانات-بكالوريوس'!$A$5:$A$208,"*",'فحص-بيانات-بكالوريوس'!$K$5:$K$208,"عالية") -> 0 | I22: =COUNTIFS('فحص-بيانات-بكالوريوس'!$A$5:$A$208,"*",'فحص-بيانات-بكالوريوس'!$P$5:$P$208,"<>") -> 0
A24: ='الإعدادات واللجنة'!$B$7 -> ماجستير علوم البيانات
A25: المعيار | B25: عدد الأدلة | C25: مكتمل | D25: يحتاج تحسين | E25: غير متوفر | F25: لم يُقيَّم | G25: نسبة الاكتمال | H25: أولوية عالية | I25: راجعتها أ. فاطمة
A26: 1. إدارة البرنامج وضمان جودته | B26: =COUNTIF('فحص-بيانات-ماجستير'!$B$5:$B$230,"1. إدارة البرنامج وضمان جودته") -> 52 | C26: =COUNTIFS('فحص-بيانات-ماجستير'!$B$5:$B$230,"1. إدارة البرنامج وضمان جودته",'فحص-بيانات-ماجستير'!$I$5:$I$230,"متوفر ومكتمل") -> 0 | D26: =COUNTIFS('فحص-بيانات-ماجستير'!$B$5:$B$230,"1. إدارة البرنامج وضمان جودته",'فحص-بيانات-ماجستير'!$I$5:$I$230,"متوفر ويحتاج تحسين") -> 0 | E26: =COUNTIFS('فحص-بيانات-ماجستير'!$B$5:$B$230,"1. إدارة البرنامج وضمان جودته",'فحص-بيانات-ماجستير'!$I$5:$I$230,"غير متوفر") -> 0 | F26: =B26-SUM(C26:E26) -> 52 | G26: =IF(B26=0,0,C26/B26) -> 0 | H26: =COUNTIFS('فحص-بيانات-ماجستير'!$B$5:$B$230,"1. إدارة البرنامج وضمان جودته",'فحص-بيانات-ماجستير'!$K$5:$K$230,"عالية") -> 0 | I26: =COUNTIFS('فحص-بيانات-ماجستير'!$B$5:$B$230,"1. إدارة البرنامج وضمان جودته",'فحص-بيانات-ماجستير'!$P$5:$P$230,"<>") -> 0
A27: 2. التعليم والتعلم | B27: =COUNTIF('فحص-بيانات-ماجستير'!$B$5:$B$230,"2. التعليم والتعلم") -> 68 | C27: =COUNTIFS('فحص-بيانات-ماجستير'!$B$5:$B$230,"2. التعليم والتعلم",'فحص-بيانات-ماجستير'!$I$5:$I$230,"متوفر ومكتمل") -> 0 | D27: =COUNTIFS('فحص-بيانات-ماجستير'!$B$5:$B$230,"2. التعليم والتعلم",'فحص-بيانات-ماجستير'!$I$5:$I$230,"متوفر ويحتاج تحسين") -> 0 | E27: =COUNTIFS('فحص-بيانات-ماجستير'!$B$5:$B$230,"2. التعليم والتعلم",'فحص-بيانات-ماجستير'!$I$5:$I$230,"غير متوفر") -> 0 | F27: =B27-SUM(C27:E27) -> 68 | G27: =IF(B27=0,0,C27/B27) -> 0 | H27: =COUNTIFS('فحص-بيانات-ماجستير'!$B$5:$B$230,"2. التعليم والتعلم",'فحص-بيانات-ماجستير'!$K$5:$K$230,"عالية") -> 0 | I27: =COUNTIFS('فحص-بيانات-ماجستير'!$B$5:$B$230,"2. التعليم والتعلم",'فحص-بيانات-ماجستير'!$P$5:$P$230,"<>") -> 0
A28: 3. الطالب | B28: =COUNTIF('فحص-بيانات-ماجستير'!$B$5:$B$230,"3. الطالب") -> 28 | C28: =COUNTIFS('فحص-بيانات-ماجستير'!$B$5:$B$230,"3. الطالب",'فحص-بيانات-ماجستير'!$I$5:$I$230,"متوفر ومكتمل") -> 0 | D28: =COUNTIFS('فحص-بيانات-ماجستير'!$B$5:$B$230,"3. الطالب",'فحص-بيانات-ماجستير'!$I$5:$I$230,"متوفر ويحتاج تحسين") -> 0 | E28: =COUNTIFS('فحص-بيانات-ماجستير'!$B$5:$B$230,"3. الطالب",'فحص-بيانات-ماجستير'!$I$5:$I$230,"غير متوفر") -> 0 | F28: =B28-SUM(C28:E28) -> 28 | G28: =IF(B28=0,0,C28/B28) -> 0 | H28: =COUNTIFS('فحص-بيانات-ماجستير'!$B$5:$B$230,"3. الطالب",'فحص-بيانات-ماجستير'!$K$5:$K$230,"عالية") -> 0 | I28: =COUNTIFS('فحص-بيانات-ماجستير'!$B$5:$B$230,"3. الطالب",'فحص-بيانات-ماجستير'!$P$5:$P$230,"<>") -> 0
A29: 4. هيئة التدريس | B29: =COUNTIF('فحص-بيانات-ماجستير'!$B$5:$B$230,"4. هيئة التدريس") -> 26 | C29: =COUNTIFS('فحص-بيانات-ماجستير'!$B$5:$B$230,"4. هيئة التدريس",'فحص-بيانات-ماجستير'!$I$5:$I$230,"متوفر ومكتمل") -> 0 | D29: =COUNTIFS('فحص-بيانات-ماجستير'!$B$5:$B$230,"4. هيئة التدريس",'فحص-بيانات-ماجستير'!$I$5:$I$230,"متوفر ويحتاج تحسين") -> 0 | E29: =COUNTIFS('فحص-بيانات-ماجستير'!$B$5:$B$230,"4. هيئة التدريس",'فحص-بيانات-ماجستير'!$I$5:$I$230,"غير متوفر") -> 0 | F29: =B29-SUM(C29:E29) -> 26 | G29: =IF(B29=0,0,C29/B29) -> 0 | H29: =COUNTIFS('فحص-بيانات-ماجستير'!$B$5:$B$230,"4. هيئة التدريس",'فحص-بيانات-ماجستير'!$K$5:$K$230,"عالية") -> 0 | I29: =COUNTIFS('فحص-بيانات-ماجستير'!$B$5:$B$230,"4. هيئة التدريس",'فحص-بيانات-ماجستير'!$P$5:$P$230,"<>") -> 0
A30: 5. مصادر التعلم والمرافق والتجهيزات | B30: =COUNTIF('فحص-بيانات-ماجستير'!$B$5:$B$230,"5. مصادر التعلم والمرافق والتجهيزات") -> 19 | C30: =COUNTIFS('فحص-بيانات-ماجستير'!$B$5:$B$230,"5. مصادر التعلم والمرافق والتجهيزات",'فحص-بيانات-ماجستير'!$I$5:$I$230,"متوفر ومكتمل") -> 0 | D30: =COUNTIFS('فحص-بيانات-ماجستير'!$B$5:$B$230,"5. مصادر التعلم والمرافق والتجهيزات",'فحص-بيانات-ماجستير'!$I$5:$I$230,"متوفر ويحتاج تحسين") -> 0 | E30: =COUNTIFS('فحص-بيانات-ماجستير'!$B$5:$B$230,"5. مصادر التعلم والمرافق والتجهيزات",'فحص-بيانات-ماجستير'!$I$5:$I$230,"غير متوفر") -> 0 | F30: =B30-SUM(C30:E30) -> 19 | G30: =IF(B30=0,0,C30/B30) -> 0 | H30: =COUNTIFS('فحص-بيانات-ماجستير'!$B$5:$B$230,"5. مصادر التعلم والمرافق والتجهيزات",'فحص-بيانات-ماجستير'!$K$5:$K$230,"عالية") -> 0 | I30: =COUNTIFS('فحص-بيانات-ماجستير'!$B$5:$B$230,"5. مصادر التعلم والمرافق والتجهيزات",'فحص-بيانات-ماجستير'!$P$5:$P$230,"<>") -> 0
A31: 6. البحث والمشاريع | B31: =COUNTIF('فحص-بيانات-ماجستير'!$B$5:$B$230,"6. البحث والمشاريع") -> 33 | C31: =COUNTIFS('فحص-بيانات-ماجستير'!$B$5:$B$230,"6. البحث والمشاريع",'فحص-بيانات-ماجستير'!$I$5:$I$230,"متوفر ومكتمل") -> 0 | D31: =COUNTIFS('فحص-بيانات-ماجستير'!$B$5:$B$230,"6. البحث والمشاريع",'فحص-بيانات-ماجستير'!$I$5:$I$230,"متوفر ويحتاج تحسين") -> 0 | E31: =COUNTIFS('فحص-بيانات-ماجستير'!$B$5:$B$230,"6. البحث والمشاريع",'فحص-بيانات-ماجستير'!$I$5:$I$230,"غير متوفر") -> 0 | F31: =B31-SUM(C31:E31) -> 33 | G31: =IF(B31=0,0,C31/B31) -> 0 | H31: =COUNTIFS('فحص-بيانات-ماجستير'!$B$5:$B$230,"6. البحث والمشاريع",'فحص-بيانات-ماجستير'!$K$5:$K$230,"عالية") -> 0 | I31: =COUNTIFS('فحص-بيانات-ماجستير'!$B$5:$B$230,"6. البحث والمشاريع",'فحص-بيانات-ماجستير'!$P$5:$P$230,"<>") -> 0
A32: المحكات الأساسية ★ | B32: =COUNTIF('فحص-بيانات-ماجستير'!$D$5:$D$230,"★") -> 69 | C32: =COUNTIFS('فحص-بيانات-ماجستير'!$D$5:$D$230,"★",'فحص-بيانات-ماجستير'!$I$5:$I$230,"متوفر ومكتمل") -> 0 | D32: =COUNTIFS('فحص-بيانات-ماجستير'!$D$5:$D$230,"★",'فحص-بيانات-ماجستير'!$I$5:$I$230,"متوفر ويحتاج تحسين") -> 0 | E32: =COUNTIFS('فحص-بيانات-ماجستير'!$D$5:$D$230,"★",'فحص-بيانات-ماجستير'!$I$5:$I$230,"غير متوفر") -> 0 | F32: =B32-SUM(C32:E32) -> 69 | G32: =IF(B32=0,0,C32/B32) -> 0 | H32: =COUNTIFS('فحص-بيانات-ماجستير'!$D$5:$D$230,"★",'فحص-بيانات-ماجستير'!$K$5:$K$230,"عالية") -> 0 | I32: =COUNTIFS('فحص-بيانات-ماجستير'!$D$5:$D$230,"★",'فحص-بيانات-ماجستير'!$P$5:$P$230,"<>") -> 0
A33: الإجمالي | B33: =COUNTIF('فحص-بيانات-ماجستير'!$A$5:$A$230,"*") -> 226 | C33: =COUNTIFS('فحص-بيانات-ماجستير'!$A$5:$A$230,"*",'فحص-بيانات-ماجستير'!$I$5:$I$230,"متوفر ومكتمل") -> 0 | D33: =COUNTIFS('فحص-بيانات-ماجستير'!$A$5:$A$230,"*",'فحص-بيانات-ماجستير'!$I$5:$I$230,"متوفر ويحتاج تحسين") -> 0 | E33: =COUNTIFS('فحص-بيانات-ماجستير'!$A$5:$A$230,"*",'فحص-بيانات-ماجستير'!$I$5:$I$230,"غير متوفر") -> 0 | F33: =B33-SUM(C33:E33) -> 226 | G33: =IF(B33=0,0,C33/B33) -> 0 | H33: =COUNTIFS('فحص-بيانات-ماجستير'!$A$5:$A$230,"*",'فحص-بيانات-ماجستير'!$K$5:$K$230,"عالية") -> 0 | I33: =COUNTIFS('فحص-بيانات-ماجستير'!$A$5:$A$230,"*",'فحص-بيانات-ماجستير'!$P$5:$P$230,"<>") -> 0
A35: إنجاز الأعضاء (للبرامج الثلاثة)
A36: الاسم | B36: الأدلة المسندة | C36: تم تقييمها | D36: نسبة الإنجاز | E36: راجعتها أ. فاطمة | F36: تحتاج تعديل
A37: ='الإعدادات واللجنة'!$B$15 -> د. سلطان بن سعيد الشمراني | B37: =COUNTIFS('فحص-حاسب-بكالوريوس'!$H$5:$H$208,'الإعدادات واللجنة'!$B$15)+COUNTIFS('فحص-بيانات-بكالوريوس'!$H$5:$H$208,'الإعدادات واللجنة'!$B$15)+COUNTIFS('فحص-بيانات-ماجستير'!$H$5:$H$230,'الإعدادات واللجنة'!$B$15) -> 117 | C37: =COUNTIFS('فحص-حاسب-بكالوريوس'!$H$5:$H$208,'الإعدادات واللجنة'!$B$15,'فحص-حاسب-بكالوريوس'!$I$5:$I$208,"<>")+COUNTIFS('فحص-بيانات-بكالوريوس'!$H$5:$H$208,'الإعدادات واللجنة'!$B$15,'فحص-بيانات-بكالوريوس'!$I$5:$I$208,"<>")+COUNTIFS('فحص-بيانات-ماجستير'!$H$5:$H$230,'الإعدادات واللجنة'!$B$15,'فحص-بيانات-ماجستير'!$I$5:$I$230,"<>") -> 0 | D37: =IF(B37=0,0,C37/B37) -> 0 | E37: =COUNTIFS('فحص-حاسب-بكالوريوس'!$H$5:$H$208,'الإعدادات واللجنة'!$B$15,'فحص-حاسب-بكالوريوس'!$P$5:$P$208,"<>")+COUNTIFS('فحص-بيانات-بكالوريوس'!$H$5:$H$208,'الإعدادات واللجنة'!$B$15,'فحص-بيانات-بكالوريوس'!$P$5:$P$208,"<>")+COUNTIFS('فحص-بيانات-ماجستير'!$H$5:$H$230,'الإعدادات واللجنة'!$B$15,'فحص-بيانات-ماجستير'!$P$5:$P$230,"<>") -> 0 | F37: =COUNTIFS('فحص-حاسب-بكالوريوس'!$H$5:$H$208,'الإعدادات واللجنة'!$B$15,'فحص-حاسب-بكالوريوس'!$P$5:$P$208,"تحتاج تعديل")+COUNTIFS('فحص-بيانات-بكالوريوس'!$H$5:$H$208,'الإعدادات واللجنة'!$B$15,'فحص-بيانات-بكالوريوس'!$P$5:$P$208,"تحتاج تعديل")+COUNTIFS('فحص-بيانات-ماجستير'!$H$5:$H$230,'الإعدادات واللجنة'!$B$15,'فحص-بيانات-ماجستير'!$P$5:$P$230,"تحتاج تعديل") -> 0
A38: ='الإعدادات واللجنة'!$B$16 -> د. احمد بن عوض البشري | B38: =COUNTIFS('فحص-حاسب-بكالوريوس'!$H$5:$H$208,'الإعدادات واللجنة'!$B$16)+COUNTIFS('فحص-بيانات-بكالوريوس'!$H$5:$H$208,'الإعدادات واللجنة'!$B$16)+COUNTIFS('فحص-بيانات-ماجستير'!$H$5:$H$230,'الإعدادات واللجنة'!$B$16) -> 141 | C38: =COUNTIFS('فحص-حاسب-بكالوريوس'!$H$5:$H$208,'الإعدادات واللجنة'!$B$16,'فحص-حاسب-بكالوريوس'!$I$5:$I$208,"<>")+COUNTIFS('فحص-بيانات-بكالوريوس'!$H$5:$H$208,'الإعدادات واللجنة'!$B$16,'فحص-بيانات-بكالوريوس'!$I$5:$I$208,"<>")+COUNTIFS('فحص-بيانات-ماجستير'!$H$5:$H$230,'الإعدادات واللجنة'!$B$16,'فحص-بيانات-ماجستير'!$I$5:$I$230,"<>") -> 0 | D38: =IF(B38=0,0,C38/B38) -> 0 | E38: =COUNTIFS('فحص-حاسب-بكالوريوس'!$H$5:$H$208,'الإعدادات واللجنة'!$B$16,'فحص-حاسب-بكالوريوس'!$P$5:$P$208,"<>")+COUNTIFS('فحص-بيانات-بكالوريوس'!$H$5:$H$208,'الإعدادات واللجنة'!$B$16,'فحص-بيانات-بكالوريوس'!$P$5:$P$208,"<>")+COUNTIFS('فحص-بيانات-ماجستير'!$H$5:$H$230,'الإعدادات واللجنة'!$B$16,'فحص-بيانات-ماجستير'!$P$5:$P$230,"<>") -> 0 | F38: =COUNTIFS('فحص-حاسب-بكالوريوس'!$H$5:$H$208,'الإعدادات واللجنة'!$B$16,'فحص-حاسب-بكالوريوس'!$P$5:$P$208,"تحتاج تعديل")+COUNTIFS('فحص-بيانات-بكالوريوس'!$H$5:$H$208,'الإعدادات واللجنة'!$B$16,'فحص-بيانات-بكالوريوس'!$P$5:$P$208,"تحتاج تعديل")+COUNTIFS('فحص-بيانات-ماجستير'!$H$5:$H$230,'الإعدادات واللجنة'!$B$16,'فحص-بيانات-ماجستير'!$P$5:$P$230,"تحتاج تعديل") -> 0
A39: ='الإعدادات واللجنة'!$B$17 -> د. يثرب بنت سعد القحطاني | B39: =COUNTIFS('فحص-حاسب-بكالوريوس'!$H$5:$H$208,'الإعدادات واللجنة'!$B$17)+COUNTIFS('فحص-بيانات-بكالوريوس'!$H$5:$H$208,'الإعدادات واللجنة'!$B$17)+COUNTIFS('فحص-بيانات-ماجستير'!$H$5:$H$230,'الإعدادات واللجنة'!$B$17) -> 77 | C39: =COUNTIFS('فحص-حاسب-بكالوريوس'!$H$5:$H$208,'الإعدادات واللجنة'!$B$17,'فحص-حاسب-بكالوريوس'!$I$5:$I$208,"<>")+COUNTIFS('فحص-بيانات-بكالوريوس'!$H$5:$H$208,'الإعدادات واللجنة'!$B$17,'فحص-بيانات-بكالوريوس'!$I$5:$I$208,"<>")+COUNTIFS('فحص-بيانات-ماجستير'!$H$5:$H$230,'الإعدادات واللجنة'!$B$17,'فحص-بيانات-ماجستير'!$I$5:$I$230,"<>") -> 0 | D39: =IF(B39=0,0,C39/B39) -> 0 | E39: =COUNTIFS('فحص-حاسب-بكالوريوس'!$H$5:$H$208,'الإعدادات واللجنة'!$B$17,'فحص-حاسب-بكالوريوس'!$P$5:$P$208,"<>")+COUNTIFS('فحص-بيانات-بكالوريوس'!$H$5:$H$208,'الإعدادات واللجنة'!$B$17,'فحص-بيانات-بكالوريوس'!$P$5:$P$208,"<>")+COUNTIFS('فحص-بيانات-ماجستير'!$H$5:$H$230,'الإعدادات واللجنة'!$B$17,'فحص-بيانات-ماجستير'!$P$5:$P$230,"<>") -> 0 | F39: =COUNTIFS('فحص-حاسب-بكالوريوس'!$H$5:$H$208,'الإعدادات واللجنة'!$B$17,'فحص-حاسب-بكالوريوس'!$P$5:$P$208,"تحتاج تعديل")+COUNTIFS('فحص-بيانات-بكالوريوس'!$H$5:$H$208,'الإعدادات واللجنة'!$B$17,'فحص-بيانات-بكالوريوس'!$P$5:$P$208,"تحتاج تعديل")+COUNTIFS('فحص-بيانات-ماجستير'!$H$5:$H$230,'الإعدادات واللجنة'!$B$17,'فحص-بيانات-ماجستير'!$P$5:$P$230,"تحتاج تعديل") -> 0
A40: ='الإعدادات واللجنة'!$B$18 -> د. عبدالله بن محمد البركاتي | B40: =COUNTIFS('فحص-حاسب-بكالوريوس'!$H$5:$H$208,'الإعدادات واللجنة'!$B$18)+COUNTIFS('فحص-بيانات-بكالوريوس'!$H$5:$H$208,'الإعدادات واللجنة'!$B$18)+COUNTIFS('فحص-بيانات-ماجستير'!$H$5:$H$230,'الإعدادات واللجنة'!$B$18) -> 92 | C40: =COUNTIFS('فحص-حاسب-بكالوريوس'!$H$5:$H$208,'الإعدادات واللجنة'!$B$18,'فحص-حاسب-بكالوريوس'!$I$5:$I$208,"<>")+COUNTIFS('فحص-بيانات-بكالوريوس'!$H$5:$H$208,'الإعدادات واللجنة'!$B$18,'فحص-بيانات-بكالوريوس'!$I$5:$I$208,"<>")+COUNTIFS('فحص-بيانات-ماجستير'!$H$5:$H$230,'الإعدادات واللجنة'!$B$18,'فحص-بيانات-ماجستير'!$I$5:$I$230,"<>") -> 0 | D40: =IF(B40=0,0,C40/B40) -> 0 | E40: =COUNTIFS('فحص-حاسب-بكالوريوس'!$H$5:$H$208,'الإعدادات واللجنة'!$B$18,'فحص-حاسب-بكالوريوس'!$P$5:$P$208,"<>")+COUNTIFS('فحص-بيانات-بكالوريوس'!$H$5:$H$208,'الإعدادات واللجنة'!$B$18,'فحص-بيانات-بكالوريوس'!$P$5:$P$208,"<>")+COUNTIFS('فحص-بيانات-ماجستير'!$H$5:$H$230,'الإعدادات واللجنة'!$B$18,'فحص-بيانات-ماجستير'!$P$5:$P$230,"<>") -> 0 | F40: =COUNTIFS('فحص-حاسب-بكالوريوس'!$H$5:$H$208,'الإعدادات واللجنة'!$B$18,'فحص-حاسب-بكالوريوس'!$P$5:$P$208,"تحتاج تعديل")+COUNTIFS('فحص-بيانات-بكالوريوس'!$H$5:$H$208,'الإعدادات واللجنة'!$B$18,'فحص-بيانات-بكالوريوس'!$P$5:$P$208,"تحتاج تعديل")+COUNTIFS('فحص-بيانات-ماجستير'!$H$5:$H$230,'الإعدادات واللجنة'!$B$18,'فحص-بيانات-ماجستير'!$P$5:$P$230,"تحتاج تعديل") -> 0
A41: ='الإعدادات واللجنة'!$B$19 -> د. عمر بن محمد موسى | B41: =COUNTIFS('فحص-حاسب-بكالوريوس'!$H$5:$H$208,'الإعدادات واللجنة'!$B$19)+COUNTIFS('فحص-بيانات-بكالوريوس'!$H$5:$H$208,'الإعدادات واللجنة'!$B$19)+COUNTIFS('فحص-بيانات-ماجستير'!$H$5:$H$230,'الإعدادات واللجنة'!$B$19) -> 111 | C41: =COUNTIFS('فحص-حاسب-بكالوريوس'!$H$5:$H$208,'الإعدادات واللجنة'!$B$19,'فحص-حاسب-بكالوريوس'!$I$5:$I$208,"<>")+COUNTIFS('فحص-بيانات-بكالوريوس'!$H$5:$H$208,'الإعدادات واللجنة'!$B$19,'فحص-بيانات-بكالوريوس'!$I$5:$I$208,"<>")+COUNTIFS('فحص-بيانات-ماجستير'!$H$5:$H$230,'الإعدادات واللجنة'!$B$19,'فحص-بيانات-ماجستير'!$I$5:$I$230,"<>") -> 0 | D41: =IF(B41=0,0,C41/B41) -> 0 | E41: =COUNTIFS('فحص-حاسب-بكالوريوس'!$H$5:$H$208,'الإعدادات واللجنة'!$B$19,'فحص-حاسب-بكالوريوس'!$P$5:$P$208,"<>")+COUNTIFS('فحص-بيانات-بكالوريوس'!$H$5:$H$208,'الإعدادات واللجنة'!$B$19,'فحص-بيانات-بكالوريوس'!$P$5:$P$208,"<>")+COUNTIFS('فحص-بيانات-ماجستير'!$H$5:$H$230,'الإعدادات واللجنة'!$B$19,'فحص-بيانات-ماجستير'!$P$5:$P$230,"<>") -> 0 | F41: =COUNTIFS('فحص-حاسب-بكالوريوس'!$H$5:$H$208,'الإعدادات واللجنة'!$B$19,'فحص-حاسب-بكالوريوس'!$P$5:$P$208,"تحتاج تعديل")+COUNTIFS('فحص-بيانات-بكالوريوس'!$H$5:$H$208,'الإعدادات واللجنة'!$B$19,'فحص-بيانات-بكالوريوس'!$P$5:$P$208,"تحتاج تعديل")+COUNTIFS('فحص-بيانات-ماجستير'!$H$5:$H$230,'الإعدادات واللجنة'!$B$19,'فحص-بيانات-ماجستير'!$P$5:$P$230,"تحتاج تعديل") -> 0
A42: ='الإعدادات واللجنة'!$B$20 -> د. حسن بن سعد القحطاني | B42: =COUNTIFS('فحص-حاسب-بكالوريوس'!$H$5:$H$208,'الإعدادات واللجنة'!$B$20)+COUNTIFS('فحص-بيانات-بكالوريوس'!$H$5:$H$208,'الإعدادات واللجنة'!$B$20)+COUNTIFS('فحص-بيانات-ماجستير'!$H$5:$H$230,'الإعدادات واللجنة'!$B$20) -> 96 | C42: =COUNTIFS('فحص-حاسب-بكالوريوس'!$H$5:$H$208,'الإعدادات واللجنة'!$B$20,'فحص-حاسب-بكالوريوس'!$I$5:$I$208,"<>")+COUNTIFS('فحص-بيانات-بكالوريوس'!$H$5:$H$208,'الإعدادات واللجنة'!$B$20,'فحص-بيانات-بكالوريوس'!$I$5:$I$208,"<>")+COUNTIFS('فحص-بيانات-ماجستير'!$H$5:$H$230,'الإعدادات واللجنة'!$B$20,'فحص-بيانات-ماجستير'!$I$5:$I$230,"<>") -> 0 | D42: =IF(B42=0,0,C42/B42) -> 0 | E42: =COUNTIFS('فحص-حاسب-بكالوريوس'!$H$5:$H$208,'الإعدادات واللجنة'!$B$20,'فحص-حاسب-بكالوريوس'!$P$5:$P$208,"<>")+COUNTIFS('فحص-بيانات-بكالوريوس'!$H$5:$H$208,'الإعدادات واللجنة'!$B$20,'فحص-بيانات-بكالوريوس'!$P$5:$P$208,"<>")+COUNTIFS('فحص-بيانات-ماجستير'!$H$5:$H$230,'الإعدادات واللجنة'!$B$20,'فحص-بيانات-ماجستير'!$P$5:$P$230,"<>") -> 0 | F42: =COUNTIFS('فحص-حاسب-بكالوريوس'!$H$5:$H$208,'الإعدادات واللجنة'!$B$20,'فحص-حاسب-بكالوريوس'!$P$5:$P$208,"تحتاج تعديل")+COUNTIFS('فحص-بيانات-بكالوريوس'!$H$5:$H$208,'الإعدادات واللجنة'!$B$20,'فحص-بيانات-بكالوريوس'!$P$5:$P$208,"تحتاج تعديل")+COUNTIFS('فحص-بيانات-ماجستير'!$H$5:$H$230,'الإعدادات واللجنة'!$B$20,'فحص-بيانات-ماجستير'!$P$5:$P$230,"تحتاج تعديل") -> 0
A44: أكثر أسباب النقص
A45: سبب النقص | B45: ='الإعدادات واللجنة'!$B$5 -> بكالوريوس علوم الحاسب | C45: ='الإعدادات واللجنة'!$B$6 -> بكالوريوس علوم البيانات | D45: ='الإعدادات واللجنة'!$B$7 -> ماجستير علوم البيانات
...

Sheet متطلبات التقدم للاعتماد
A1: متطلبات التقدم للاعتماد البرامجي وأين تُعالج في خطتنا
A2: مرجع للجنة: متطلبات التقدم كما في عرض المركز الوطني للتقويم والاعتماد الأكاديمي (النماذج المعتمدة إصدار 2024)، ومكان معالجة كل بند والمسؤول عنه.
A4: م | B4: المتطلب | C4: المطلوب تحديداً | D4: أين يُعالج | E4: المسؤول | F4: ملاحظة
A5: شرطا الأهلية
A6: 1 | B6: الترخيص | C6: قرار إنشاء البرنامج أو قرار ترخيصه النهائي | D6: محقق – يُجلب القرار | E6: ='الإعدادات واللجنة'!$B$12 -> د. نهلة بنت سعد القثامي | F6: قرار الإنشاء أو الترخيص لكل برنامج من البرامج الثلاثة
A7: 2 | B7: دفعة متخرجة | C7: تخرّج دفعة واحدة على الأقل من البرنامج | D7: محقق | E7: — | F7: تخرّجت دفعات من البرامج الثلاثة
A8: متطلبات التقدم
A9: 3 | B9: الإطار الوطني للمؤهلات (TP-150) | C9: تقرير اتساق البرنامج مع الإطار الوطني | D9: لجنة الجودة | E9: ='الإعدادات واللجنة'!$B$13 -> د. عبير بنت عبدالله راجحي | F9: تُعرض حالته في اجتماعي الأسبوعين 4 و7
A10: 4 | B10: التوصيفات (TP-151، TP-153، TP-155) | C10: توصيف البرنامج وجميع المقررات والخبرة الميدانية (إن وُجدت) وفق نماذج المركز | D10: لجنة الجودة | E10: ='الإعدادات واللجنة'!$B$13 -> د. عبير بنت عبدالله راجحي | F10: تُعرض حالتها في اجتماعي الأسبوعين 4 و7
A11: 5 | B11: التقارير السنوية (TP-152، TP-154، TP-156) | C11: تقرير البرنامج لآخر سنتين وتقارير المقررات والخبرة الميدانية | D11: لجنة الجودة | E11: ='الإعدادات واللجنة'!$B$13 -> د. عبير بنت عبدالله راجحي | F11: تُعرض حالتها في اجتماعي الأسبوعين 4 و7
A12: 6 | B12: نواتج التعلم | C12: خطة تقييم نواتج التعلم وتقاريرها | D12: لجنة الجودة | E12: ='الإعدادات واللجنة'!$B$13 -> د. عبير بنت عبدالله راجحي | F12: تُعرض حالتها في اجتماعي الأسبوعين 4 و7
A13: 7 | B13: مؤشرات الأداء | C13: القياس والمقارنة المرجعية لآخر ثلاث سنوات | D13: لجنة الجودة | E13: ='الإعدادات واللجنة'!$B$13 -> د. عبير بنت عبدالله راجحي | F13: تُعرض حالتها في اجتماعي الأسبوعين 4 و7
A14: 8 | B14: الدراسة الذاتية (TP-102) | C14: مقاييس التقويم الذاتي والتقرير والأدلة الداعمة | D14: المرحلة التالية بعد الخطة | E14: — | F14: تُكتب بعد جمع الأدلة ومعالجة الفجوات
A15: تُستكمل معها
A16: 9 | B16: أدلة البرنامج ولوائحه | C16: أدلة البرنامج وسياساته ولوائحه | D16: داخل المحكات في أوراق الفحص | E16: أعضاء الفحص | F16: مثل 1-1-5 و1-1-7 و1-1-8 و1-1-9 و2-2-1 و3-0-1 و3-0-2 و3-0-3
A17: 10 | B17: نظام ضمان الجودة | C17: نظام جودة البرنامج المنسجم مع النظام المؤسسي | D17: المحك 1-2-1 في أوراق الفحص | E17: ='الإعدادات واللجنة'!$B$20 -> د. حسن بن سعد القحطاني
A18: 11 | B18: اللجنة الاستشارية للبرنامج | C18: قرار تشكيلها ومهامها ومحاضرها | D18: المحك 1-1-6 في أوراق الفحص | E18: ='الإعدادات واللجنة'!$B$15 -> د. سلطان بن سعيد الشمراني
A19: 12 | B19: الوضع المؤسسي | C19: المؤسسة معتمدة أو مؤهلة مؤسسياً | D19: محقق | E19: — | F19: الجامعة حاصلة على الاعتماد المؤسسي الكامل

Sheet مراجعة الرسالة (مقترح)
A1: نموذج مقترح: مراجعة رسالة البرنامج وأهدافه (للنقاش في اللجنة)
A2: لا يوجد نموذج مستقل من الهيئة لهذه المراجعة؛ الرسالة والأهداف تُكتب رسمياً في توصيف البرنامج (TP-151) ويُسأل عنها في الدراسة الذاتية (TP-102). يُستحسن سؤال عمادة الجودة عن نموذج داخلي قبل اعتماد هذا المقترح.
A3: الهدف: الحصول على أدلة المحك 1-1-1 الأربعة لكل برنامج: مصفوفة الاتساق، وإعلان الرسالة على الموقع، والخطة التشغيلية، وتقرير استطلاع المستفيدين.
A5: ① الأسئلة الثلاثة
A6: 1 | B6: هل هي متسقة؟ | C6: كل هدف من أهداف البرنامج مرتبط بهدف من أهداف الكلية والجامعة (مصفوفة الاتساق).
A7: 2 | B7: هل هي واضحة ومعروفة؟ | C7: استطلاع قصير لأعضاء هيئة التدريس والطلاب والخريجين وجهات التوظيف.
A8: 3 | B8: هل هي مطبّقة؟ | C8: الخطة التشغيلية ونواتج التعلم مبنية على هذه الأهداف.
A10: ② الخطوات
A11: م | B11: الخطوة | C11: المخرج | D11: ='الإعدادات واللجنة'!$B$5 -> بكالوريوس علوم الحاسب | E11: ='الإعدادات واللجنة'!$B$6 -> بكالوريوس علوم البيانات | F11: ='الإعدادات واللجنة'!$B$7 -> ماجستير علوم البيانات
A12: 1 | B12: جمع الوثائق: رسالة الجامعة والكلية وأهدافهما، ورسالة البرنامج الحالية، والتوصيف، والخطة التشغيلية | C12: ملف الوثائق | D12: لم تبدأ | E12: لم تبدأ | F12: لم تبدأ
A13: 2 | B13: الفحص بقائمة التحقق ③ | C13: قائمة تحقق معبأة | D13: لم تبدأ | E13: لم تبدأ | F13: لم تبدأ
A14: 3 | B14: تعبئة مصفوفة الاتساق ④ | C14: مصفوفة الاتساق | D14: لم تبدأ | E14: لم تبدأ | F14: لم تبدأ
A15: 4 | B15: الاستطلاع ⑤ (نموذج إلكتروني لمدة أسبوع) | C15: تقرير الاستطلاع | D15: لم تبدأ | E15: لم تبدأ | F15: لم تبدأ
A16: 5 | B16: القرار: إبقاء / تعديل طفيف / إعادة صياغة | C16: توصية اللجنة | D16: لم تبدأ | E16: لم تبدأ | F16: لم تبدأ
A17: 6 | B17: الاعتماد من المجلس (إن عُدّلت) | C17: محضر الاعتماد | D17: لم تبدأ | E17: لم تبدأ | F17: لم تبدأ
A18: 7 | B18: النشر: الموقع، دليل الطالب، التوصيف | C18: روابط النشر | D18: لم تبدأ | E18: لم تبدأ | F18: لم تبدأ
A20: ③ قائمة التحقق
A21: م | B21: السؤال | D21: ='الإعدادات واللجنة'!$B$5 -> بكالوريوس علوم الحاسب | E21: ='الإعدادات واللجنة'!$B$6 -> بكالوريوس علوم البيانات | F21: ='الإعدادات واللجنة'!$B$7 -> ماجستير علوم البيانات
A22: 1 | B22: الرسالة مختصرة وواضحة ويسهل تذكرها
A23: 2 | B23: الرسالة تبيّن ما يميز البرنامج
A24: 3 | B24: الرسالة متسقة مع رسالة الكلية والجامعة
A25: 4 | B25: الأهداف تغطي التعليم والبحث وخدمة المجتمع
A26: 5 | B26: الأهداف محددة وقابلة للقياس ولكل هدف مؤشر
A27: 6 | B27: الأهداف مرتبطة بنواتج التعلم وخصائص الخريجين
A28: 7 | B28: الأهداف تراعي احتياجات سوق العمل
A29: 8 | B29: الرسالة والأهداف معتمدة ومنشورة
A30: 9 | B30: الخطة التشغيلية مبنية على الأهداف
A32: ④ مصفوفة الاتساق (لكل برنامج نسخة) – ضع ✓ عند وجود ارتباط
A33: م | B33: هدف البرنامج | C33: هدف الكلية ... | D33: هدف الكلية ... | E33: هدف الجامعة ... | F33: هدف الجامعة ...
A34: 1 | B34: الهدف 1: ...
A35: 2 | B35: الهدف 2: ...
A36: 3 | B36: الهدف 3: ...
A37: 4 | B37: الهدف 4: ...
A38: 5 | B38: الهدف 5: ...
A40: ⑤ أسئلة الاستطلاع (موافق بشدة ← غير موافق بشدة)
A41: 1 | B41: أعرف رسالة البرنامج وأهدافه.
A42: 2 | B42: الرسالة والأهداف واضحة ومفهومة.
A43: 3 | B43: الرسالة تعبّر عما يميز البرنامج.
A44: 4 | B44: أنشطة البرنامج ومقرراته تحقق رسالته وأهدافه.
A45: 5 | B45: الأهداف تلبي احتياجات سوق العمل.
...

Sheet فحص-حاسب-بكالوريوس
A1: ="فحص الأدلة – "&'الإعدادات واللجنة'!$B$5 -> فحص الأدلة – بكالوريوس علوم الحاسب
A2: عبّئ الخلايا الصفراء: حالة الدليل، وإن كان ناقصاً: السبب والإجراء والموعد، ثم رابط الدليل. الأعمدة P–Q لأ. فاطمة. الصفوف المظللة = محكات أساسية ★
A4: الرمز | B4: المعيار | C4: نص المحك | D4: أساسي | E4: م | F4: الدليل / الشاهد | G4: مصدر الدليل | H4: المسؤول | I4: حالة الدليل | J4: سبب النقص | K4: الأولوية | L4: الإجراء المطلوب | M4: الموعد | N4: رابط الدليل في المستودع | O4: ملاحظات العضو | P4: مراجعة أ. فاطمة | Q4: ملاحظات المراجعة
A5: 1-1-1 | B5: 1. إدارة البرنامج وضمان جودته | C5: تتسق رسالة البرنامج وأهدافه مع رسالة المؤسسة/الكلية وتوجّه جميع عملياته وأنشطته. | E5: 1 | F5: مصفوفة اتساق رسالة وأهداف البرنامج مع رسالة وأهداف الجامعة والكلية. | G5: الدليل الاسترشادي | H5: =IFERROR(INDEX('الإعدادات واللجنة'!$C$24:$C$32,MATCH(LEFT(A5,3),'الإعدادات واللجنة'!$A$24:$A$32,0)),"") -> د. سلطان بن سعيد الشمراني | K5: =IF(OR(I5="",I5="متوفر ومكتمل"),"",IF(OR(D5="★",I5="غير متوفر"),"عالية","متوسطة"))
A6: 1-1-1 | B6: 1. إدارة البرنامج وضمان جودته | E6: 2 | F6: إعلان رسالة وأهداف البرنامج على الموقع الإلكتروني للبرنامج. | G6: الدليل الاسترشادي | H6: =IFERROR(INDEX('الإعدادات واللجنة'!$C$24:$C$32,MATCH(LEFT(A6,3),'الإعدادات واللجنة'!$A$24:$A$32,0)),"") -> د. سلطان بن سعيد الشمراني | K6: =IF(OR(I6="",I6="متوفر ومكتمل"),"",IF(OR(D6="★",I6="غير متوفر"),"عالية","متوسطة"))
A7: 1-1-1 | B7: 1. إدارة البرنامج وضمان جودته | E7: 3 | F7: الخطة التشغيلية للبرنامج وتقاريرها وتشمل البحث العلمي وخدمة المجتمع. | G7: الدليل الاسترشادي | H7: =IFERROR(INDEX('الإعدادات واللجنة'!$C$24:$C$32,MATCH(LEFT(A7,3),'الإعدادات واللجنة'!$A$24:$A$32,0)),"") -> د. سلطان بن سعيد الشمراني | K7: =IF(OR(I7="",I7="متوفر ومكتمل"),"",IF(OR(D7="★",I7="غير متوفر"),"عالية","متوسطة"))
A8: 1-1-1 | B8: 1. إدارة البرنامج وضمان جودته | E8: 4 | F8: تقرير استطلاع رأي المستفيدين حول وضوح ونشر الرسالة والأهداف. | G8: الدليل الاسترشادي | H8: =IFERROR(INDEX('الإعدادات واللجنة'!$C$24:$C$32,MATCH(LEFT(A8,3),'الإعدادات واللجنة'!$A$24:$A$32,0)),"") -> د. سلطان بن سعيد الشمراني | K8: =IF(OR(I8="",I8="متوفر ومكتمل"),"",IF(OR(D8="★",I8="غير متوفر"),"عالية","متوسطة"))
A9: 1-1-2 | B9: 1. إدارة البرنامج وضمان جودته | C9: يتوفر لدى البرنامج العدد الكافي من الكوادر المؤهلة للقيام بالمهام الإدارية والمهنية والفنية، ولهم مهام وصلاحيات محددة. | D9: ★ | E9: 1 | F9: قاعدة بيانات محدثة لأعضاء هيئة التدريس بالبرنامج والإداريين والفنيين. | G9: الدليل الاسترشادي | H9: =IFERROR(INDEX('الإعدادات واللجنة'!$C$24:$C$32,MATCH(LEFT(A9,3),'الإعدادات واللجنة'!$A$24:$A$32,0)),"") -> د. سلطان بن سعيد الشمراني | K9: =IF(OR(I9="",I9="متوفر ومكتمل"),"",IF(OR(D9="★",I9="غير متوفر"),"عالية","متوسطة"))
A10: 1-1-2 | B10: 1. إدارة البرنامج وضمان جودته | D10: ★ | E10: 2 | F10: السير الذاتية لأعضاء هيئة التدريس، وقيادات البرنامج، والإداريين، والفنيين. | G10: الدليل الاسترشادي | H10: =IFERROR(INDEX('الإعدادات واللجنة'!$C$24:$C$32,MATCH(LEFT(A10,3),'الإعدادات واللجنة'!$A$24:$A$32,0)),"") -> د. سلطان بن سعيد الشمراني | K10: =IF(OR(I10="",I10="متوفر ومكتمل"),"",IF(OR(D10="★",I10="غير متوفر"),"عالية","متوسطة"))
A11: 1-1-2 | B11: 1. إدارة البرنامج وضمان جودته | D11: ★ | E11: 3 | F11: نماذج من تشكيلات اللجان بالبرنامج محددة المهام. | G11: الدليل الاسترشادي | H11: =IFERROR(INDEX('الإعدادات واللجنة'!$C$24:$C$32,MATCH(LEFT(A11,3),'الإعدادات واللجنة'!$A$24:$A$32,0)),"") -> د. سلطان بن سعيد الشمراني | K11: =IF(OR(I11="",I11="متوفر ومكتمل"),"",IF(OR(D11="★",I11="غير متوفر"),"عالية","متوسطة"))
A12: 1-1-2 | B12: 1. إدارة البرنامج وضمان جودته | D12: ★ | E12: 4 | F12: معايير اختيار القيادات الأكاديمية والإدارية. | G12: الدليل الاسترشادي | H12: =IFERROR(INDEX('الإعدادات واللجنة'!$C$24:$C$32,MATCH(LEFT(A12,3),'الإعدادات واللجنة'!$A$24:$A$32,0)),"") -> د. سلطان بن سعيد الشمراني | K12: =IF(OR(I12="",I12="متوفر ومكتمل"),"",IF(OR(D12="★",I12="غير متوفر"),"عالية","متوسطة"))
A13: 1-1-2 | B13: 1. إدارة البرنامج وضمان جودته | D13: ★ | E13: 5 | F13: استبانة تقييم القيادات الأكاديمية والإدارية بالبرنامج. | G13: الدليل الاسترشادي | H13: =IFERROR(INDEX('الإعدادات واللجنة'!$C$24:$C$32,MATCH(LEFT(A13,3),'الإعدادات واللجنة'!$A$24:$A$32,0)),"") -> د. سلطان بن سعيد الشمراني | K13: =IF(OR(I13="",I13="متوفر ومكتمل"),"",IF(OR(D13="★",I13="غير متوفر"),"عالية","متوسطة"))
A14: 1-1-3 | B14: 1. إدارة البرنامج وضمان جودته | C14: يتوفر للبرنامج منظومة تحفيزية وبيئة أكاديمية داعمة. | E14: 1 | F14: دليل جوائز التميز بالكلية/الجامعة. | G14: الدليل الاسترشادي | H14: =IFERROR(INDEX('الإعدادات واللجنة'!$C$24:$C$32,MATCH(LEFT(A14,3),'الإعدادات واللجنة'!$A$24:$A$32,0)),"") -> د. سلطان بن سعيد الشمراني | K14: =IF(OR(I14="",I14="متوفر ومكتمل"),"",IF(OR(D14="★",I14="غير متوفر"),"عالية","متوسطة"))
A15: 1-1-3 | B15: 1. إدارة البرنامج وضمان جودته | E15: 2 | F15: نماذج من شهادات (تميز/تقدير) منسوبي البرنامج والإداريين والفنيين. | G15: الدليل الاسترشادي | H15: =IFERROR(INDEX('الإعدادات واللجنة'!$C$24:$C$32,MATCH(LEFT(A15,3),'الإعدادات واللجنة'!$A$24:$A$32,0)),"") -> د. سلطان بن سعيد الشمراني | K15: =IF(OR(I15="",I15="متوفر ومكتمل"),"",IF(OR(D15="★",I15="غير متوفر"),"عالية","متوسطة"))
A16: 1-1-3 | B16: 1. إدارة البرنامج وضمان جودته | E16: 3 | F16: قائمة بالمرافق والتجهيزات التعليمية والبحثية للبرنامج. | G16: الدليل الاسترشادي | H16: =IFERROR(INDEX('الإعدادات واللجنة'!$C$24:$C$32,MATCH(LEFT(A16,3),'الإعدادات واللجنة'!$A$24:$A$32,0)),"") -> د. سلطان بن سعيد الشمراني | K16: =IF(OR(I16="",I16="متوفر ومكتمل"),"",IF(OR(D16="★",I16="غير متوفر"),"عالية","متوسطة"))
A17: 1-1-3 | B17: 1. إدارة البرنامج وضمان جودته | E17: 4 | F17: قائمة بالمرافق والتجهيزات الخاصة بالأنشطة اللاصفية بالبرنامج. | G17: الدليل الاسترشادي | H17: =IFERROR(INDEX('الإعدادات واللجنة'!$C$24:$C$32,MATCH(LEFT(A17,3),'الإعدادات واللجنة'!$A$24:$A$32,0)),"") -> د. سلطان بن سعيد الشمراني | K17: =IF(OR(I17="",I17="متوفر ومكتمل"),"",IF(OR(D17="★",I17="غير متوفر"),"عالية","متوسطة"))
A18: 1-1-3 | B18: 1. إدارة البرنامج وضمان جودته | E18: 5 | F18: تقييمات أعضاء هيئة التدريس والإداريين والفنيين والطلاب للمناخ التنظيمي والبيئة الأكاديمية. | G18: الدليل الاسترشادي | H18: =IFERROR(INDEX('الإعدادات واللجنة'!$C$24:$C$32,MATCH(LEFT(A18,3),'الإعدادات واللجنة'!$A$24:$A$32,0)),"") -> د. سلطان بن سعيد الشمراني | K18: =IF(OR(I18="",I18="متوفر ومكتمل"),"",IF(OR(D18="★",I18="غير متوفر"),"عالية","متوسطة"))
A19: 1-1-4 | B19: 1. إدارة البرنامج وضمان جودته | C19: يتم القياس المستمر لمؤشرات أداء البرنامج الرئيسة، وتُتخذ الإجراءات اللازمة للتحسين. | E19: 1 | F19: تقرير مؤشرات الأداء الرئيسة للبرنامج. | G19: الدليل الاسترشادي | H19: =IFERROR(INDEX('الإعدادات واللجنة'!$C$24:$C$32,MATCH(LEFT(A19,3),'الإعدادات واللجنة'!$A$24:$A$32,0)),"") -> د. سلطان بن سعيد الشمراني | K19: =IF(OR(I19="",I19="متوفر ومكتمل"),"",IF(OR(D19="★",I19="غير متوفر"),"عالية","متوسطة"))
A20: 1-1-4 | B20: 1. إدارة البرنامج وضمان جودته | E20: 2 | F20: تقرير إنجاز الخطة التشغيلية للبرنامج مع خطة التحسين. | G20: الدليل الاسترشادي | H20: =IFERROR(INDEX('الإعدادات واللجنة'!$C$24:$C$32,MATCH(LEFT(A20,3),'الإعدادات واللجنة'!$A$24:$A$32,0)),"") -> د. سلطان بن سعيد الشمراني | K20: =IF(OR(I20="",I20="متوفر ومكتمل"),"",IF(OR(D20="★",I20="غير متوفر"),"عالية","متوسطة"))
A21: 1-1-5 | B21: 1. إدارة البرنامج وضمان جودته | C21: يوثّق البرنامج وينشر السياسات والحقوق والواجبات الخاصة بمنسوبيه بصورة معلنة، ويطبق آليات تضمن النزاهة والعدالة والمساواة في جميع ممارساته الأكاديمية والإدارية بين شطري الطلاب والطالبات والفروع (إن وجدت). | E21: 1 | F21: لوحة/دليل موضح فيه السياسات والحقوق والواجبات وتكون معلنة. | G21: الدليل الاسترشادي | H21: =IFERROR(INDEX('الإعدادات واللجنة'!$C$24:$C$32,MATCH(LEFT(A21,3),'الإعدادات واللجنة'!$A$24:$A$32,0)),"") -> د. سلطان بن سعيد الشمراني | K21: =IF(OR(I21="",I21="متوفر ومكتمل"),"",IF(OR(D21="★",I21="غير متوفر"),"عالية","متوسطة"))
A22: 1-1-5 | B22: 1. إدارة البرنامج وضمان جودته | E22: 2 | F22: استطلاع رأي أعضاء هيئة التدريس والطلبة عن تطبيق إدارة البرنامج لآليات النزاهة والعدالة والمساواة. | G22: الدليل الاسترشادي | H22: =IFERROR(INDEX('الإعدادات واللجنة'!$C$24:$C$32,MATCH(LEFT(A22,3),'الإعدادات واللجنة'!$A$24:$A$32,0)),"") -> د. سلطان بن سعيد الشمراني | K22: =IF(OR(I22="",I22="متوفر ومكتمل"),"",IF(OR(D22="★",I22="غير متوفر"),"عالية","متوسطة"))
A23: 1-1-5 | B23: 1. إدارة البرنامج وضمان جودته | E23: 3 | F23: الشواهد على مدى تكافؤ الإمكانيات المادية والبشرية بين شطري الطالب والطالبات. | G23: الدليل الاسترشادي | H23: =IFERROR(INDEX('الإعدادات واللجنة'!$C$24:$C$32,MATCH(LEFT(A23,3),'الإعدادات واللجنة'!$A$24:$A$32,0)),"") -> د. سلطان بن سعيد الشمراني | K23: =IF(OR(I23="",I23="متوفر ومكتمل"),"",IF(OR(D23="★",I23="غير متوفر"),"عالية","متوسطة"))
A24: 1-1-5 | B24: 1. إدارة البرنامج وضمان جودته | E24: 4 | F24: تشكيل اللجان والمجالس العاملة بالقسم بما يتضمن إشراك الجنسين والفروع (إن وجدت)، وكذا تمويل الأبحاث والمشاريع وحضور المؤتمرات. | G24: الدليل الاسترشادي | H24: =IFERROR(INDEX('الإعدادات واللجنة'!$C$24:$C$32,MATCH(LEFT(A24,3),'الإعدادات واللجنة'!$A$24:$A$32,0)),"") -> د. سلطان بن سعيد الشمراني | K24: =IF(OR(I24="",I24="متوفر ومكتمل"),"",IF(OR(D24="★",I24="غير متوفر"),"عالية","متوسطة"))
A25: 1-1-6 | B25: 1. إدارة البرنامج وضمان جودته | C25: تستفيد إدارة البرنامج من آراء المختصين والخبراء في تشكيل لجنة استشارية متنوعة الأعضاء وموضحة المهام، وتخصص البرنامج في تقييم وتطوير وتحسين أدائه. | E25: 1 | F25: قرار تشكيل اللجنة الاستشارية للبرنامج المتنوعة الأعضاء والموضح مهامها. | G25: الدليل الاسترشادي | H25: =IFERROR(INDEX('الإعدادات واللجنة'!$C$24:$C$32,MATCH(LEFT(A25,3),'الإعدادات واللجنة'!$A$24:$A$32,0)),"") -> د. سلطان بن سعيد الشمراني | K25: =IF(OR(I25="",I25="متوفر ومكتمل"),"",IF(OR(D25="★",I25="غير متوفر"),"عالية","متوسطة"))
A26: 1-1-6 | B26: 1. إدارة البرنامج وضمان جودته | E26: 2 | F26: نماذج من محاضر اللجنة الاستشارية للبرنامج متضمنة التوصيات وخطط تفعيلها. | G26: الدليل الاسترشادي | H26: =IFERROR(INDEX('الإعدادات واللجنة'!$C$24:$C$32,MATCH(LEFT(A26,3),'الإعدادات واللجنة'!$A$24:$A$32,0)),"") -> د. سلطان بن سعيد الشمراني | K26: =IF(OR(I26="",I26="متوفر ومكتمل"),"",IF(OR(D26="★",I26="غير متوفر"),"عالية","متوسطة"))
A27: 1-1-6 | B27: 1. إدارة البرنامج وضمان جودته | E27: 3 | F27: تقرير استطلاع رأي جهات التوظيف حول الخريجين وتوصيات وخطط التحسين. | G27: الدليل الاسترشادي | H27: =IFERROR(INDEX('الإعدادات واللجنة'!$C$24:$C$32,MATCH(LEFT(A27,3),'الإعدادات واللجنة'!$A$24:$A$32,0)),"") -> د. سلطان بن سعيد الشمراني | K27: =IF(OR(I27="",I27="متوفر ومكتمل"),"",IF(OR(D27="★",I27="غير متوفر"),"عالية","متوسطة"))
A28: 1-1-6 | B28: 1. إدارة البرنامج وضمان جودته | E28: 4 | F28: محاضر مجلس القسم متضمنة مناقشة توصيات اللجنة الاستشارية واستطلاع رأي جهات التوظيف وأي مقترحات تطوير من خبراء التخصص. | G28: الدليل الاسترشادي | H28: =IFERROR(INDEX('الإعدادات واللجنة'!$C$24:$C$32,MATCH(LEFT(A28,3),'الإعدادات واللجنة'!$A$24:$A$32,0)),"") -> د. سلطان بن سعيد الشمراني | K28: =IF(OR(I28="",I28="متوفر ومكتمل"),"",IF(OR(D28="★",I28="غير متوفر"),"عالية","متوسطة"))
A29: 1-1-7 | B29: 1. إدارة البرنامج وضمان جودته | C29: تتيح إدارة البرنامج معلومات موثوقة ومحدّثة تُبرز إنجازات البرنامج بما يتناسب مع احتياجات المستفيدين. | E29: 1 | F29: الدليل التعريفي للبرنامج. | G29: الدليل الاسترشادي | H29: =IFERROR(INDEX('الإعدادات واللجنة'!$C$24:$C$32,MATCH(LEFT(A29,3),'الإعدادات واللجنة'!$A$24:$A$32,0)),"") -> د. سلطان بن سعيد الشمراني | K29: =IF(OR(I29="",I29="متوفر ومكتمل"),"",IF(OR(D29="★",I29="غير متوفر"),"عالية","متوسطة"))
A30: 1-1-7 | B30: 1. إدارة البرنامج وضمان جودته | E30: 2 | F30: الموقع الإلكتروني للبرنامج متضمناً توصيف البرنامج والمقررات الدراسية وأنشطته وإنجازاته محدّثاً. | G30: الدليل الاسترشادي | H30: =IFERROR(INDEX('الإعدادات واللجنة'!$C$24:$C$32,MATCH(LEFT(A30,3),'الإعدادات واللجنة'!$A$24:$A$32,0)),"") -> د. سلطان بن سعيد الشمراني | K30: =IF(OR(I30="",I30="متوفر ومكتمل"),"",IF(OR(D30="★",I30="غير متوفر"),"عالية","متوسطة"))
A31: 1-1-7 | B31: 1. إدارة البرنامج وضمان جودته | E31: 3 | F31: أنشطة لجنة خدمة المجتمع للتعريف بالبرنامج وإمكاناته والخدمات التي يقدمها للمجتمع. | G31: الدليل الاسترشادي | H31: =IFERROR(INDEX('الإعدادات واللجنة'!$C$24:$C$32,MATCH(LEFT(A31,3),'الإعدادات واللجنة'!$A$24:$A$32,0)),"") -> د. سلطان بن سعيد الشمراني | K31: =IF(OR(I31="",I31="متوفر ومكتمل"),"",IF(OR(D31="★",I31="غير متوفر"),"عالية","متوسطة"))
A32: 1-1-7 | B32: 1. إدارة البرنامج وضمان جودته | E32: 4 | F32: نماذج من إعلانات ولقاءات التعريف بالبرنامج مع المستفيدين. | G32: الدليل الاسترشادي | H32: =IFERROR(INDEX('الإعدادات واللجنة'!$C$24:$C$32,MATCH(LEFT(A32,3),'الإعدادات واللجنة'!$A$24:$A$32,0)),"") -> د. سلطان بن سعيد الشمراني | K32: =IF(OR(I32="",I32="متوفر ومكتمل"),"",IF(OR(D32="★",I32="غير متوفر"),"عالية","متوسطة"))
A33: 1-1-7 | B33: 1. إدارة البرنامج وضمان جودته | E33: 5 | F33: نتائج استطلاع رأي المستفيدين حول إتاحة المعلومات الخاصة بالبرنامج. | G33: الدليل الاسترشادي | H33: =IFERROR(INDEX('الإعدادات واللجنة'!$C$24:$C$32,MATCH(LEFT(A33,3),'الإعدادات واللجنة'!$A$24:$A$32,0)),"") -> د. سلطان بن سعيد الشمراني | K33: =IF(OR(I33="",I33="متوفر ومكتمل"),"",IF(OR(D33="★",I33="غير متوفر"),"عالية","متوسطة"))
A34: 1-1-8 | B34: 1. إدارة البرنامج وضمان جودته | C34: تلتزم إدارة البرنامج بتفعيل قيم الأمانة العلمية وحقوق الملكية الفكرية وقواعد الممارسات الأخلاقية والسلوك القويم في جميع المجالات والأنشطة الأكاديمية والبحثية والإدارية والخدمية. | D34: ★ | E34: 1 | F34: السياسات والإجراءات الموثقة التي يطبقها البرنامج بشأن عمليات الاقتباس والملكية الفكرية للطلبة وأعضاء هيئة التدريس. | G34: الدليل الاسترشادي | H34: =IFERROR(INDEX('الإعدادات واللجنة'!$C$24:$C$32,MATCH(LEFT(A34,3),'الإعدادات واللجنة'!$A$24:$A$32,0)),"") -> د. سلطان بن سعيد الشمراني | K34: =IF(OR(I34="",I34="متوفر ومكتمل"),"",IF(OR(D34="★",I34="غير متوفر"),"عالية","متوسطة"))
A35: 1-1-8 | B35: 1. إدارة البرنامج وضمان جودته | D35: ★ | E35: 2 | F35: دليل الإطار الأخلاقي للطلبة ومنسوبي الجامعة. | G35: الدليل الاسترشادي | H35: =IFERROR(INDEX('الإعدادات واللجنة'!$C$24:$C$32,MATCH(LEFT(A35,3),'الإعدادات واللجنة'!$A$24:$A$32,0)),"") -> د. سلطان بن سعيد الشمراني | K35: =IF(OR(I35="",I35="متوفر ومكتمل"),"",IF(OR(D35="★",I35="غير متوفر"),"عالية","متوسطة"))
A36: 1-1-8 | B36: 1. إدارة البرنامج وضمان جودته | D36: ★ | E36: 3 | F36: دليل أخلاقيات البحث العلمي. | G36: الدليل الاسترشادي | H36: =IFERROR(INDEX('الإعدادات واللجنة'!$C$24:$C$32,MATCH(LEFT(A36,3),'الإعدادات واللجنة'!$A$24:$A$32,0)),"") -> د. سلطان بن سعيد الشمراني | K36: =IF(OR(I36="",I36="متوفر ومكتمل"),"",IF(OR(D36="★",I36="غير متوفر"),"عالية","متوسطة"))
A37: 1-1-8 | B37: 1. إدارة البرنامج وضمان جودته | D37: ★ | E37: 4 | F37: قائمة بالدورات التدريبية المتعلقة بقيم الأمانة العلمية وحقوق الملكية الفكرية وقواعد الممارسات الأخلاقية. | G37: الدليل الاسترشادي | H37: =IFERROR(INDEX('الإعدادات واللجنة'!$C$24:$C$32,MATCH(LEFT(A37,3),'الإعدادات واللجنة'!$A$24:$A$32,0)),"") -> د. سلطان بن سعيد الشمراني | K37: =IF(OR(I37="",I37="متوفر ومكتمل"),"",IF(OR(D37="★",I37="غير متوفر"),"عالية","متوسطة"))
